(0.000) SELECT @@SQL_AUTO_IS_NULL; args=None
(0.000) SET SESSION TRANSACTION ISOLATION LEVEL READ COMMITTED; args=None
(0.001) SELECT `django_session`.`session_key`, `django_session`.`session_data`, `django_session`.`expire_date` FROM `django_session` WHERE (`django_session`.`expire_date` > '2019-01-05 21:03:07.272409' AND `django_session`.`session_key` = 'h9tkpwnc85p71oh60fjq1kmxy4nqdlti'); args=('2019-01-05 21:03:07.272409', 'h9tkpwnc85p71oh60fjq1kmxy4nqdlti')
(0.001) SELECT `auth_user`.`id`, `auth_user`.`password`, `auth_user`.`last_login`, `auth_user`.`is_superuser`, `auth_user`.`username`, `auth_user`.`first_name`, `auth_user`.`last_name`, `auth_user`.`email`, `auth_user`.`is_staff`, `auth_user`.`is_active`, `auth_user`.`date_joined` FROM `auth_user` WHERE `auth_user`.`id` = 1; args=(1,)
(0.001) SELECT `deployer_deployer`.`id`, `deployer_deployer`.`queue_id`, `deployer_deployer`.`url` FROM `deployer_deployer`; args=()
Exception while resolving variable 'hide_label' in template 'rest_framework/horizontal/input.html'.
Traceback (most recent call last):
  File "/usr/local/lib/python3.6/site-packages/django/template/base.py", line 829, in _resolve_lookup
    current = current[bit]
KeyError: 'hide_label'

During handling of the above exception, another exception occurred:

Traceback (most recent call last):
  File "/usr/local/lib/python3.6/site-packages/django/template/base.py", line 837, in _resolve_lookup
    current = getattr(current, bit)
AttributeError: 'dict' object has no attribute 'hide_label'

During handling of the above exception, another exception occurred:

Traceback (most recent call last):
  File "/usr/local/lib/python3.6/site-packages/django/template/base.py", line 843, in _resolve_lookup
    current = current[int(bit)]
ValueError: invalid literal for int() with base 10: 'hide_label'

During handling of the above exception, another exception occurred:

Traceback (most recent call last):
  File "/usr/local/lib/python3.6/site-packages/django/template/base.py", line 850, in _resolve_lookup
    (bit, current))  # missing attribute
django.template.base.VariableDoesNotExist: Failed lookup for key [hide_label] in {'base_template': 'input.html', 'input_type': 'text', 'template_pack': 'rest_framework/horizontal', 'renderer': <rest_framework.renderers.HTMLFormRenderer object at 0x7f735c381550>}
Exception while resolving variable 'placeholder' in template 'rest_framework/horizontal/input.html'.
Traceback (most recent call last):
  File "/usr/local/lib/python3.6/site-packages/django/template/base.py", line 829, in _resolve_lookup
    current = current[bit]
KeyError: 'placeholder'

During handling of the above exception, another exception occurred:

Traceback (most recent call last):
  File "/usr/local/lib/python3.6/site-packages/django/template/base.py", line 837, in _resolve_lookup
    current = getattr(current, bit)
AttributeError: 'dict' object has no attribute 'placeholder'

During handling of the above exception, another exception occurred:

Traceback (most recent call last):
  File "/usr/local/lib/python3.6/site-packages/django/template/base.py", line 843, in _resolve_lookup
    current = current[int(bit)]
ValueError: invalid literal for int() with base 10: 'placeholder'

During handling of the above exception, another exception occurred:

Traceback (most recent call last):
  File "/usr/local/lib/python3.6/site-packages/django/template/base.py", line 850, in _resolve_lookup
    (bit, current))  # missing attribute
django.template.base.VariableDoesNotExist: Failed lookup for key [placeholder] in {'base_template': 'input.html', 'input_type': 'text', 'template_pack': 'rest_framework/horizontal', 'renderer': <rest_framework.renderers.HTMLFormRenderer object at 0x7f735c381550>}
Exception while resolving variable 'autofocus' in template 'rest_framework/horizontal/input.html'.
Traceback (most recent call last):
  File "/usr/local/lib/python3.6/site-packages/django/template/base.py", line 829, in _resolve_lookup
    current = current[bit]
KeyError: 'autofocus'

During handling of the above exception, another exception occurred:

Traceback (most recent call last):
  File "/usr/local/lib/python3.6/site-packages/django/template/base.py", line 837, in _resolve_lookup
    current = getattr(current, bit)
AttributeError: 'dict' object has no attribute 'autofocus'

During handling of the above exception, another exception occurred:

Traceback (most recent call last):
  File "/usr/local/lib/python3.6/site-packages/django/template/base.py", line 843, in _resolve_lookup
    current = current[int(bit)]
ValueError: invalid literal for int() with base 10: 'autofocus'

During handling of the above exception, another exception occurred:

Traceback (most recent call last):
  File "/usr/local/lib/python3.6/site-packages/django/template/base.py", line 850, in _resolve_lookup
    (bit, current))  # missing attribute
django.template.base.VariableDoesNotExist: Failed lookup for key [autofocus] in {'base_template': 'input.html', 'input_type': 'text', 'template_pack': 'rest_framework/horizontal', 'renderer': <rest_framework.renderers.HTMLFormRenderer object at 0x7f735c381550>}
Exception while resolving variable 'hide_label' in template 'rest_framework/horizontal/textarea.html'.
Traceback (most recent call last):
  File "/usr/local/lib/python3.6/site-packages/django/template/base.py", line 829, in _resolve_lookup
    current = current[bit]
KeyError: 'hide_label'

During handling of the above exception, another exception occurred:

Traceback (most recent call last):
  File "/usr/local/lib/python3.6/site-packages/django/template/base.py", line 837, in _resolve_lookup
    current = getattr(current, bit)
AttributeError: 'dict' object has no attribute 'hide_label'

During handling of the above exception, another exception occurred:

Traceback (most recent call last):
  File "/usr/local/lib/python3.6/site-packages/django/template/base.py", line 843, in _resolve_lookup
    current = current[int(bit)]
ValueError: invalid literal for int() with base 10: 'hide_label'

During handling of the above exception, another exception occurred:

Traceback (most recent call last):
  File "/usr/local/lib/python3.6/site-packages/django/template/base.py", line 850, in _resolve_lookup
    (bit, current))  # missing attribute
django.template.base.VariableDoesNotExist: Failed lookup for key [hide_label] in {'base_template': 'textarea.html', 'input_type': 'text', 'template_pack': 'rest_framework/horizontal', 'renderer': <rest_framework.renderers.HTMLFormRenderer object at 0x7f735c381550>}
Exception while resolving variable 'placeholder' in template 'rest_framework/horizontal/textarea.html'.
Traceback (most recent call last):
  File "/usr/local/lib/python3.6/site-packages/django/template/base.py", line 829, in _resolve_lookup
    current = current[bit]
KeyError: 'placeholder'

During handling of the above exception, another exception occurred:

Traceback (most recent call last):
  File "/usr/local/lib/python3.6/site-packages/django/template/base.py", line 837, in _resolve_lookup
    current = getattr(current, bit)
AttributeError: 'dict' object has no attribute 'placeholder'

During handling of the above exception, another exception occurred:

Traceback (most recent call last):
  File "/usr/local/lib/python3.6/site-packages/django/template/base.py", line 843, in _resolve_lookup
    current = current[int(bit)]
ValueError: invalid literal for int() with base 10: 'placeholder'

During handling of the above exception, another exception occurred:

Traceback (most recent call last):
  File "/usr/local/lib/python3.6/site-packages/django/template/base.py", line 850, in _resolve_lookup
    (bit, current))  # missing attribute
django.template.base.VariableDoesNotExist: Failed lookup for key [placeholder] in {'base_template': 'textarea.html', 'input_type': 'text', 'template_pack': 'rest_framework/horizontal', 'renderer': <rest_framework.renderers.HTMLFormRenderer object at 0x7f735c381550>}
Exception while resolving variable 'rows' in template 'rest_framework/horizontal/textarea.html'.
Traceback (most recent call last):
  File "/usr/local/lib/python3.6/site-packages/django/template/base.py", line 829, in _resolve_lookup
    current = current[bit]
KeyError: 'rows'

During handling of the above exception, another exception occurred:

Traceback (most recent call last):
  File "/usr/local/lib/python3.6/site-packages/django/template/base.py", line 837, in _resolve_lookup
    current = getattr(current, bit)
AttributeError: 'dict' object has no attribute 'rows'

During handling of the above exception, another exception occurred:

Traceback (most recent call last):
  File "/usr/local/lib/python3.6/site-packages/django/template/base.py", line 843, in _resolve_lookup
    current = current[int(bit)]
ValueError: invalid literal for int() with base 10: 'rows'

During handling of the above exception, another exception occurred:

Traceback (most recent call last):
  File "/usr/local/lib/python3.6/site-packages/django/template/base.py", line 850, in _resolve_lookup
    (bit, current))  # missing attribute
django.template.base.VariableDoesNotExist: Failed lookup for key [rows] in {'base_template': 'textarea.html', 'input_type': 'text', 'template_pack': 'rest_framework/horizontal', 'renderer': <rest_framework.renderers.HTMLFormRenderer object at 0x7f735c381550>}
"GET /api/v1/deploys HTTP/1.1" 200 8811
"GET /api/v1/deploys HTTP/1.1" 200 8811
"GET /static/rest_framework/css/prettify.css HTTP/1.1" 304 0
"GET /static/rest_framework/css/prettify.css HTTP/1.1" 304 0
"GET /static/rest_framework/css/default.css HTTP/1.1" 304 0
"GET /static/rest_framework/js/jquery-3.3.1.min.js HTTP/1.1" 304 0
"GET /static/rest_framework/css/default.css HTTP/1.1" 304 0
"GET /static/rest_framework/css/bootstrap-tweaks.css HTTP/1.1" 304 0
"GET /static/rest_framework/js/ajax-form.js HTTP/1.1" 304 0
"GET /static/rest_framework/js/jquery-3.3.1.min.js HTTP/1.1" 304 0
"GET /static/rest_framework/css/bootstrap-tweaks.css HTTP/1.1" 304 0
"GET /static/rest_framework/js/ajax-form.js HTTP/1.1" 304 0
"GET /static/rest_framework/css/bootstrap.min.css HTTP/1.1" 304 0
"GET /static/rest_framework/css/bootstrap.min.css HTTP/1.1" 304 0
"GET /static/rest_framework/js/csrf.js HTTP/1.1" 304 0
"GET /static/rest_framework/js/csrf.js HTTP/1.1" 304 0
"GET /static/rest_framework/js/bootstrap.min.js HTTP/1.1" 304 0
"GET /static/rest_framework/js/bootstrap.min.js HTTP/1.1" 304 0
"GET /static/rest_framework/js/prettify-min.js HTTP/1.1" 304 0
"GET /static/rest_framework/js/prettify-min.js HTTP/1.1" 304 0
"GET /static/rest_framework/js/default.js HTTP/1.1" 304 0
"GET /static/rest_framework/js/default.js HTTP/1.1" 304 0
"GET /static/rest_framework/img/grid.png HTTP/1.1" 304 0
"GET /static/rest_framework/img/grid.png HTTP/1.1" 304 0
(0.000) SELECT @@SQL_AUTO_IS_NULL; args=None
(0.000) SET SESSION TRANSACTION ISOLATION LEVEL READ COMMITTED; args=None
(0.002) SHOW FULL TABLES; args=None
(0.000) SELECT `django_migrations`.`app`, `django_migrations`.`name` FROM `django_migrations`; args=()
(0.000) SELECT @@SQL_AUTO_IS_NULL; args=None
(0.000) SET SESSION TRANSACTION ISOLATION LEVEL READ COMMITTED; args=None
(0.001) SELECT `django_session`.`session_key`, `django_session`.`session_data`, `django_session`.`expire_date` FROM `django_session` WHERE (`django_session`.`expire_date` > '2019-01-05 21:04:11.883956' AND `django_session`.`session_key` = 'h9tkpwnc85p71oh60fjq1kmxy4nqdlti'); args=('2019-01-05 21:04:11.883956', 'h9tkpwnc85p71oh60fjq1kmxy4nqdlti')
(0.002) SELECT `auth_user`.`id`, `auth_user`.`password`, `auth_user`.`last_login`, `auth_user`.`is_superuser`, `auth_user`.`username`, `auth_user`.`first_name`, `auth_user`.`last_name`, `auth_user`.`email`, `auth_user`.`is_staff`, `auth_user`.`is_active`, `auth_user`.`date_joined` FROM `auth_user` WHERE `auth_user`.`id` = 1; args=(1,)
(0.002) SELECT `deployer_deployer`.`id`, `deployer_deployer`.`queue_id`, `deployer_deployer`.`url` FROM `deployer_deployer`; args=()
Exception while resolving variable 'hide_label' in template 'rest_framework/horizontal/input.html'.
Traceback (most recent call last):
  File "/usr/local/lib/python3.6/site-packages/django/template/base.py", line 829, in _resolve_lookup
    current = current[bit]
KeyError: 'hide_label'

During handling of the above exception, another exception occurred:

Traceback (most recent call last):
  File "/usr/local/lib/python3.6/site-packages/django/template/base.py", line 837, in _resolve_lookup
    current = getattr(current, bit)
AttributeError: 'dict' object has no attribute 'hide_label'

During handling of the above exception, another exception occurred:

Traceback (most recent call last):
  File "/usr/local/lib/python3.6/site-packages/django/template/base.py", line 843, in _resolve_lookup
    current = current[int(bit)]
ValueError: invalid literal for int() with base 10: 'hide_label'

During handling of the above exception, another exception occurred:

Traceback (most recent call last):
  File "/usr/local/lib/python3.6/site-packages/django/template/base.py", line 850, in _resolve_lookup
    (bit, current))  # missing attribute
django.template.base.VariableDoesNotExist: Failed lookup for key [hide_label] in {'base_template': 'input.html', 'input_type': 'text', 'template_pack': 'rest_framework/horizontal', 'renderer': <rest_framework.renderers.HTMLFormRenderer object at 0x7f75081e8630>}
Exception while resolving variable 'placeholder' in template 'rest_framework/horizontal/input.html'.
Traceback (most recent call last):
  File "/usr/local/lib/python3.6/site-packages/django/template/base.py", line 829, in _resolve_lookup
    current = current[bit]
KeyError: 'placeholder'

During handling of the above exception, another exception occurred:

Traceback (most recent call last):
  File "/usr/local/lib/python3.6/site-packages/django/template/base.py", line 837, in _resolve_lookup
    current = getattr(current, bit)
AttributeError: 'dict' object has no attribute 'placeholder'

During handling of the above exception, another exception occurred:

Traceback (most recent call last):
  File "/usr/local/lib/python3.6/site-packages/django/template/base.py", line 843, in _resolve_lookup
    current = current[int(bit)]
ValueError: invalid literal for int() with base 10: 'placeholder'

During handling of the above exception, another exception occurred:

Traceback (most recent call last):
  File "/usr/local/lib/python3.6/site-packages/django/template/base.py", line 850, in _resolve_lookup
    (bit, current))  # missing attribute
django.template.base.VariableDoesNotExist: Failed lookup for key [placeholder] in {'base_template': 'input.html', 'input_type': 'text', 'template_pack': 'rest_framework/horizontal', 'renderer': <rest_framework.renderers.HTMLFormRenderer object at 0x7f75081e8630>}
Exception while resolving variable 'autofocus' in template 'rest_framework/horizontal/input.html'.
Traceback (most recent call last):
  File "/usr/local/lib/python3.6/site-packages/django/template/base.py", line 829, in _resolve_lookup
    current = current[bit]
KeyError: 'autofocus'

During handling of the above exception, another exception occurred:

Traceback (most recent call last):
  File "/usr/local/lib/python3.6/site-packages/django/template/base.py", line 837, in _resolve_lookup
    current = getattr(current, bit)
AttributeError: 'dict' object has no attribute 'autofocus'

During handling of the above exception, another exception occurred:

Traceback (most recent call last):
  File "/usr/local/lib/python3.6/site-packages/django/template/base.py", line 843, in _resolve_lookup
    current = current[int(bit)]
ValueError: invalid literal for int() with base 10: 'autofocus'

During handling of the above exception, another exception occurred:

Traceback (most recent call last):
  File "/usr/local/lib/python3.6/site-packages/django/template/base.py", line 850, in _resolve_lookup
    (bit, current))  # missing attribute
django.template.base.VariableDoesNotExist: Failed lookup for key [autofocus] in {'base_template': 'input.html', 'input_type': 'text', 'template_pack': 'rest_framework/horizontal', 'renderer': <rest_framework.renderers.HTMLFormRenderer object at 0x7f75081e8630>}
Exception while resolving variable 'hide_label' in template 'rest_framework/horizontal/textarea.html'.
Traceback (most recent call last):
  File "/usr/local/lib/python3.6/site-packages/django/template/base.py", line 829, in _resolve_lookup
    current = current[bit]
KeyError: 'hide_label'

During handling of the above exception, another exception occurred:

Traceback (most recent call last):
  File "/usr/local/lib/python3.6/site-packages/django/template/base.py", line 837, in _resolve_lookup
    current = getattr(current, bit)
AttributeError: 'dict' object has no attribute 'hide_label'

During handling of the above exception, another exception occurred:

Traceback (most recent call last):
  File "/usr/local/lib/python3.6/site-packages/django/template/base.py", line 843, in _resolve_lookup
    current = current[int(bit)]
ValueError: invalid literal for int() with base 10: 'hide_label'

During handling of the above exception, another exception occurred:

Traceback (most recent call last):
  File "/usr/local/lib/python3.6/site-packages/django/template/base.py", line 850, in _resolve_lookup
    (bit, current))  # missing attribute
django.template.base.VariableDoesNotExist: Failed lookup for key [hide_label] in {'base_template': 'textarea.html', 'input_type': 'text', 'template_pack': 'rest_framework/horizontal', 'renderer': <rest_framework.renderers.HTMLFormRenderer object at 0x7f75081e8630>}
Exception while resolving variable 'placeholder' in template 'rest_framework/horizontal/textarea.html'.
Traceback (most recent call last):
  File "/usr/local/lib/python3.6/site-packages/django/template/base.py", line 829, in _resolve_lookup
    current = current[bit]
KeyError: 'placeholder'

During handling of the above exception, another exception occurred:

Traceback (most recent call last):
  File "/usr/local/lib/python3.6/site-packages/django/template/base.py", line 837, in _resolve_lookup
    current = getattr(current, bit)
AttributeError: 'dict' object has no attribute 'placeholder'

During handling of the above exception, another exception occurred:

Traceback (most recent call last):
  File "/usr/local/lib/python3.6/site-packages/django/template/base.py", line 843, in _resolve_lookup
    current = current[int(bit)]
ValueError: invalid literal for int() with base 10: 'placeholder'

During handling of the above exception, another exception occurred:

Traceback (most recent call last):
  File "/usr/local/lib/python3.6/site-packages/django/template/base.py", line 850, in _resolve_lookup
    (bit, current))  # missing attribute
django.template.base.VariableDoesNotExist: Failed lookup for key [placeholder] in {'base_template': 'textarea.html', 'input_type': 'text', 'template_pack': 'rest_framework/horizontal', 'renderer': <rest_framework.renderers.HTMLFormRenderer object at 0x7f75081e8630>}
Exception while resolving variable 'rows' in template 'rest_framework/horizontal/textarea.html'.
Traceback (most recent call last):
  File "/usr/local/lib/python3.6/site-packages/django/template/base.py", line 829, in _resolve_lookup
    current = current[bit]
KeyError: 'rows'

During handling of the above exception, another exception occurred:

Traceback (most recent call last):
  File "/usr/local/lib/python3.6/site-packages/django/template/base.py", line 837, in _resolve_lookup
    current = getattr(current, bit)
AttributeError: 'dict' object has no attribute 'rows'

During handling of the above exception, another exception occurred:

Traceback (most recent call last):
  File "/usr/local/lib/python3.6/site-packages/django/template/base.py", line 843, in _resolve_lookup
    current = current[int(bit)]
ValueError: invalid literal for int() with base 10: 'rows'

During handling of the above exception, another exception occurred:

Traceback (most recent call last):
  File "/usr/local/lib/python3.6/site-packages/django/template/base.py", line 850, in _resolve_lookup
    (bit, current))  # missing attribute
django.template.base.VariableDoesNotExist: Failed lookup for key [rows] in {'base_template': 'textarea.html', 'input_type': 'text', 'template_pack': 'rest_framework/horizontal', 'renderer': <rest_framework.renderers.HTMLFormRenderer object at 0x7f75081e8630>}
"GET /api/v1/deploys HTTP/1.1" 200 8811
"GET /api/v1/deploys HTTP/1.1" 200 8811
"GET /static/rest_framework/css/bootstrap.min.css HTTP/1.1" 304 0
"GET /static/rest_framework/css/bootstrap.min.css HTTP/1.1" 304 0
"GET /static/rest_framework/css/bootstrap-tweaks.css HTTP/1.1" 304 0
"GET /static/rest_framework/css/prettify.css HTTP/1.1" 304 0
"GET /static/rest_framework/css/bootstrap-tweaks.css HTTP/1.1" 304 0
"GET /static/rest_framework/css/prettify.css HTTP/1.1" 304 0
"GET /static/rest_framework/css/default.css HTTP/1.1" 304 0
"GET /static/rest_framework/css/default.css HTTP/1.1" 304 0
"GET /static/rest_framework/js/jquery-3.3.1.min.js HTTP/1.1" 304 0
"GET /static/rest_framework/js/jquery-3.3.1.min.js HTTP/1.1" 304 0
"GET /static/rest_framework/js/ajax-form.js HTTP/1.1" 304 0
"GET /static/rest_framework/js/ajax-form.js HTTP/1.1" 304 0
"GET /static/rest_framework/js/csrf.js HTTP/1.1" 304 0
"GET /static/rest_framework/js/csrf.js HTTP/1.1" 304 0
"GET /static/rest_framework/js/bootstrap.min.js HTTP/1.1" 304 0
"GET /static/rest_framework/js/bootstrap.min.js HTTP/1.1" 304 0
"GET /static/rest_framework/js/prettify-min.js HTTP/1.1" 304 0
"GET /static/rest_framework/js/prettify-min.js HTTP/1.1" 304 0
"GET /static/rest_framework/js/default.js HTTP/1.1" 304 0
"GET /static/rest_framework/js/default.js HTTP/1.1" 304 0
"GET /static/rest_framework/img/grid.png HTTP/1.1" 304 0
"GET /static/rest_framework/img/grid.png HTTP/1.1" 304 0
(0.000) SELECT @@SQL_AUTO_IS_NULL; args=None
(0.000) SET SESSION TRANSACTION ISOLATION LEVEL READ COMMITTED; args=None
(0.001) SELECT `django_session`.`session_key`, `django_session`.`session_data`, `django_session`.`expire_date` FROM `django_session` WHERE (`django_session`.`expire_date` > '2019-01-05 21:04:18.900884' AND `django_session`.`session_key` = 'h9tkpwnc85p71oh60fjq1kmxy4nqdlti'); args=('2019-01-05 21:04:18.900884', 'h9tkpwnc85p71oh60fjq1kmxy4nqdlti')
(0.001) SELECT `auth_user`.`id`, `auth_user`.`password`, `auth_user`.`last_login`, `auth_user`.`is_superuser`, `auth_user`.`username`, `auth_user`.`first_name`, `auth_user`.`last_name`, `auth_user`.`email`, `auth_user`.`is_staff`, `auth_user`.`is_active`, `auth_user`.`date_joined` FROM `auth_user` WHERE `auth_user`.`id` = 1; args=(1,)
(0.000) SELECT `deployer_deployer`.`id`, `deployer_deployer`.`queue_id`, `deployer_deployer`.`url` FROM `deployer_deployer` WHERE `deployer_deployer`.`id` = 1; args=(1,)
Exception while resolving variable 'hide_label' in template 'rest_framework/horizontal/input.html'.
Traceback (most recent call last):
  File "/usr/local/lib/python3.6/site-packages/django/template/base.py", line 829, in _resolve_lookup
    current = current[bit]
KeyError: 'hide_label'

During handling of the above exception, another exception occurred:

Traceback (most recent call last):
  File "/usr/local/lib/python3.6/site-packages/django/template/base.py", line 837, in _resolve_lookup
    current = getattr(current, bit)
AttributeError: 'dict' object has no attribute 'hide_label'

During handling of the above exception, another exception occurred:

Traceback (most recent call last):
  File "/usr/local/lib/python3.6/site-packages/django/template/base.py", line 843, in _resolve_lookup
    current = current[int(bit)]
ValueError: invalid literal for int() with base 10: 'hide_label'

During handling of the above exception, another exception occurred:

Traceback (most recent call last):
  File "/usr/local/lib/python3.6/site-packages/django/template/base.py", line 850, in _resolve_lookup
    (bit, current))  # missing attribute
django.template.base.VariableDoesNotExist: Failed lookup for key [hide_label] in {'base_template': 'input.html', 'input_type': 'text', 'template_pack': 'rest_framework/horizontal', 'renderer': <rest_framework.renderers.HTMLFormRenderer object at 0x7f75081dbef0>}
Exception while resolving variable 'placeholder' in template 'rest_framework/horizontal/input.html'.
Traceback (most recent call last):
  File "/usr/local/lib/python3.6/site-packages/django/template/base.py", line 829, in _resolve_lookup
    current = current[bit]
KeyError: 'placeholder'

During handling of the above exception, another exception occurred:

Traceback (most recent call last):
  File "/usr/local/lib/python3.6/site-packages/django/template/base.py", line 837, in _resolve_lookup
    current = getattr(current, bit)
AttributeError: 'dict' object has no attribute 'placeholder'

During handling of the above exception, another exception occurred:

Traceback (most recent call last):
  File "/usr/local/lib/python3.6/site-packages/django/template/base.py", line 843, in _resolve_lookup
    current = current[int(bit)]
ValueError: invalid literal for int() with base 10: 'placeholder'

During handling of the above exception, another exception occurred:

Traceback (most recent call last):
  File "/usr/local/lib/python3.6/site-packages/django/template/base.py", line 850, in _resolve_lookup
    (bit, current))  # missing attribute
django.template.base.VariableDoesNotExist: Failed lookup for key [placeholder] in {'base_template': 'input.html', 'input_type': 'text', 'template_pack': 'rest_framework/horizontal', 'renderer': <rest_framework.renderers.HTMLFormRenderer object at 0x7f75081dbef0>}
Exception while resolving variable 'autofocus' in template 'rest_framework/horizontal/input.html'.
Traceback (most recent call last):
  File "/usr/local/lib/python3.6/site-packages/django/template/base.py", line 829, in _resolve_lookup
    current = current[bit]
KeyError: 'autofocus'

During handling of the above exception, another exception occurred:

Traceback (most recent call last):
  File "/usr/local/lib/python3.6/site-packages/django/template/base.py", line 837, in _resolve_lookup
    current = getattr(current, bit)
AttributeError: 'dict' object has no attribute 'autofocus'

During handling of the above exception, another exception occurred:

Traceback (most recent call last):
  File "/usr/local/lib/python3.6/site-packages/django/template/base.py", line 843, in _resolve_lookup
    current = current[int(bit)]
ValueError: invalid literal for int() with base 10: 'autofocus'

During handling of the above exception, another exception occurred:

Traceback (most recent call last):
  File "/usr/local/lib/python3.6/site-packages/django/template/base.py", line 850, in _resolve_lookup
    (bit, current))  # missing attribute
django.template.base.VariableDoesNotExist: Failed lookup for key [autofocus] in {'base_template': 'input.html', 'input_type': 'text', 'template_pack': 'rest_framework/horizontal', 'renderer': <rest_framework.renderers.HTMLFormRenderer object at 0x7f75081dbef0>}
Exception while resolving variable 'hide_label' in template 'rest_framework/horizontal/textarea.html'.
Traceback (most recent call last):
  File "/usr/local/lib/python3.6/site-packages/django/template/base.py", line 829, in _resolve_lookup
    current = current[bit]
KeyError: 'hide_label'

During handling of the above exception, another exception occurred:

Traceback (most recent call last):
  File "/usr/local/lib/python3.6/site-packages/django/template/base.py", line 837, in _resolve_lookup
    current = getattr(current, bit)
AttributeError: 'dict' object has no attribute 'hide_label'

During handling of the above exception, another exception occurred:

Traceback (most recent call last):
  File "/usr/local/lib/python3.6/site-packages/django/template/base.py", line 843, in _resolve_lookup
    current = current[int(bit)]
ValueError: invalid literal for int() with base 10: 'hide_label'

During handling of the above exception, another exception occurred:

Traceback (most recent call last):
  File "/usr/local/lib/python3.6/site-packages/django/template/base.py", line 850, in _resolve_lookup
    (bit, current))  # missing attribute
django.template.base.VariableDoesNotExist: Failed lookup for key [hide_label] in {'base_template': 'textarea.html', 'input_type': 'text', 'template_pack': 'rest_framework/horizontal', 'renderer': <rest_framework.renderers.HTMLFormRenderer object at 0x7f75081dbef0>}
Exception while resolving variable 'placeholder' in template 'rest_framework/horizontal/textarea.html'.
Traceback (most recent call last):
  File "/usr/local/lib/python3.6/site-packages/django/template/base.py", line 829, in _resolve_lookup
    current = current[bit]
KeyError: 'placeholder'

During handling of the above exception, another exception occurred:

Traceback (most recent call last):
  File "/usr/local/lib/python3.6/site-packages/django/template/base.py", line 837, in _resolve_lookup
    current = getattr(current, bit)
AttributeError: 'dict' object has no attribute 'placeholder'

During handling of the above exception, another exception occurred:

Traceback (most recent call last):
  File "/usr/local/lib/python3.6/site-packages/django/template/base.py", line 843, in _resolve_lookup
    current = current[int(bit)]
ValueError: invalid literal for int() with base 10: 'placeholder'

During handling of the above exception, another exception occurred:

Traceback (most recent call last):
  File "/usr/local/lib/python3.6/site-packages/django/template/base.py", line 850, in _resolve_lookup
    (bit, current))  # missing attribute
django.template.base.VariableDoesNotExist: Failed lookup for key [placeholder] in {'base_template': 'textarea.html', 'input_type': 'text', 'template_pack': 'rest_framework/horizontal', 'renderer': <rest_framework.renderers.HTMLFormRenderer object at 0x7f75081dbef0>}
Exception while resolving variable 'rows' in template 'rest_framework/horizontal/textarea.html'.
Traceback (most recent call last):
  File "/usr/local/lib/python3.6/site-packages/django/template/base.py", line 829, in _resolve_lookup
    current = current[bit]
KeyError: 'rows'

During handling of the above exception, another exception occurred:

Traceback (most recent call last):
  File "/usr/local/lib/python3.6/site-packages/django/template/base.py", line 837, in _resolve_lookup
    current = getattr(current, bit)
AttributeError: 'dict' object has no attribute 'rows'

During handling of the above exception, another exception occurred:

Traceback (most recent call last):
  File "/usr/local/lib/python3.6/site-packages/django/template/base.py", line 843, in _resolve_lookup
    current = current[int(bit)]
ValueError: invalid literal for int() with base 10: 'rows'

During handling of the above exception, another exception occurred:

Traceback (most recent call last):
  File "/usr/local/lib/python3.6/site-packages/django/template/base.py", line 850, in _resolve_lookup
    (bit, current))  # missing attribute
django.template.base.VariableDoesNotExist: Failed lookup for key [rows] in {'base_template': 'textarea.html', 'input_type': 'text', 'template_pack': 'rest_framework/horizontal', 'renderer': <rest_framework.renderers.HTMLFormRenderer object at 0x7f75081dbef0>}
"GET /api/v1/deploys/1/ HTTP/1.1" 200 10200
"GET /api/v1/deploys/1/ HTTP/1.1" 200 10200
(0.000) SET SESSION TRANSACTION ISOLATION LEVEL READ COMMITTED; args=None
(0.001) SELECT `django_session`.`session_key`, `django_session`.`session_data`, `django_session`.`expire_date` FROM `django_session` WHERE (`django_session`.`expire_date` > '2019-01-05 21:04:22.948608' AND `django_session`.`session_key` = 'h9tkpwnc85p71oh60fjq1kmxy4nqdlti'); args=('2019-01-05 21:04:22.948608', 'h9tkpwnc85p71oh60fjq1kmxy4nqdlti')
(0.001) SELECT `auth_user`.`id`, `auth_user`.`password`, `auth_user`.`last_login`, `auth_user`.`is_superuser`, `auth_user`.`username`, `auth_user`.`first_name`, `auth_user`.`last_name`, `auth_user`.`email`, `auth_user`.`is_staff`, `auth_user`.`is_active`, `auth_user`.`date_joined` FROM `auth_user` WHERE `auth_user`.`id` = 1; args=(1,)
(0.000) SELECT `deployer_deployer`.`id`, `deployer_deployer`.`queue_id`, `deployer_deployer`.`url` FROM `deployer_deployer` WHERE `deployer_deployer`.`id` = 1; args=(1,)
Exception while resolving variable 'hide_label' in template 'rest_framework/horizontal/input.html'.
Traceback (most recent call last):
  File "/usr/local/lib/python3.6/site-packages/django/template/base.py", line 829, in _resolve_lookup
    current = current[bit]
KeyError: 'hide_label'

During handling of the above exception, another exception occurred:

Traceback (most recent call last):
  File "/usr/local/lib/python3.6/site-packages/django/template/base.py", line 837, in _resolve_lookup
    current = getattr(current, bit)
AttributeError: 'dict' object has no attribute 'hide_label'

During handling of the above exception, another exception occurred:

Traceback (most recent call last):
  File "/usr/local/lib/python3.6/site-packages/django/template/base.py", line 843, in _resolve_lookup
    current = current[int(bit)]
ValueError: invalid literal for int() with base 10: 'hide_label'

During handling of the above exception, another exception occurred:

Traceback (most recent call last):
  File "/usr/local/lib/python3.6/site-packages/django/template/base.py", line 850, in _resolve_lookup
    (bit, current))  # missing attribute
django.template.base.VariableDoesNotExist: Failed lookup for key [hide_label] in {'base_template': 'input.html', 'input_type': 'text', 'template_pack': 'rest_framework/horizontal', 'renderer': <rest_framework.renderers.HTMLFormRenderer object at 0x7f750809ee80>}
Exception while resolving variable 'placeholder' in template 'rest_framework/horizontal/input.html'.
Traceback (most recent call last):
  File "/usr/local/lib/python3.6/site-packages/django/template/base.py", line 829, in _resolve_lookup
    current = current[bit]
KeyError: 'placeholder'

During handling of the above exception, another exception occurred:

Traceback (most recent call last):
  File "/usr/local/lib/python3.6/site-packages/django/template/base.py", line 837, in _resolve_lookup
    current = getattr(current, bit)
AttributeError: 'dict' object has no attribute 'placeholder'

During handling of the above exception, another exception occurred:

Traceback (most recent call last):
  File "/usr/local/lib/python3.6/site-packages/django/template/base.py", line 843, in _resolve_lookup
    current = current[int(bit)]
ValueError: invalid literal for int() with base 10: 'placeholder'

During handling of the above exception, another exception occurred:

Traceback (most recent call last):
  File "/usr/local/lib/python3.6/site-packages/django/template/base.py", line 850, in _resolve_lookup
    (bit, current))  # missing attribute
django.template.base.VariableDoesNotExist: Failed lookup for key [placeholder] in {'base_template': 'input.html', 'input_type': 'text', 'template_pack': 'rest_framework/horizontal', 'renderer': <rest_framework.renderers.HTMLFormRenderer object at 0x7f750809ee80>}
Exception while resolving variable 'autofocus' in template 'rest_framework/horizontal/input.html'.
Traceback (most recent call last):
  File "/usr/local/lib/python3.6/site-packages/django/template/base.py", line 829, in _resolve_lookup
    current = current[bit]
KeyError: 'autofocus'

During handling of the above exception, another exception occurred:

Traceback (most recent call last):
  File "/usr/local/lib/python3.6/site-packages/django/template/base.py", line 837, in _resolve_lookup
    current = getattr(current, bit)
AttributeError: 'dict' object has no attribute 'autofocus'

During handling of the above exception, another exception occurred:

Traceback (most recent call last):
  File "/usr/local/lib/python3.6/site-packages/django/template/base.py", line 843, in _resolve_lookup
    current = current[int(bit)]
ValueError: invalid literal for int() with base 10: 'autofocus'

During handling of the above exception, another exception occurred:

Traceback (most recent call last):
  File "/usr/local/lib/python3.6/site-packages/django/template/base.py", line 850, in _resolve_lookup
    (bit, current))  # missing attribute
django.template.base.VariableDoesNotExist: Failed lookup for key [autofocus] in {'base_template': 'input.html', 'input_type': 'text', 'template_pack': 'rest_framework/horizontal', 'renderer': <rest_framework.renderers.HTMLFormRenderer object at 0x7f750809ee80>}
Exception while resolving variable 'hide_label' in template 'rest_framework/horizontal/textarea.html'.
Traceback (most recent call last):
  File "/usr/local/lib/python3.6/site-packages/django/template/base.py", line 829, in _resolve_lookup
    current = current[bit]
KeyError: 'hide_label'

During handling of the above exception, another exception occurred:

Traceback (most recent call last):
  File "/usr/local/lib/python3.6/site-packages/django/template/base.py", line 837, in _resolve_lookup
    current = getattr(current, bit)
AttributeError: 'dict' object has no attribute 'hide_label'

During handling of the above exception, another exception occurred:

Traceback (most recent call last):
  File "/usr/local/lib/python3.6/site-packages/django/template/base.py", line 843, in _resolve_lookup
    current = current[int(bit)]
ValueError: invalid literal for int() with base 10: 'hide_label'

During handling of the above exception, another exception occurred:

Traceback (most recent call last):
  File "/usr/local/lib/python3.6/site-packages/django/template/base.py", line 850, in _resolve_lookup
    (bit, current))  # missing attribute
django.template.base.VariableDoesNotExist: Failed lookup for key [hide_label] in {'base_template': 'textarea.html', 'input_type': 'text', 'template_pack': 'rest_framework/horizontal', 'renderer': <rest_framework.renderers.HTMLFormRenderer object at 0x7f750809ee80>}
Exception while resolving variable 'placeholder' in template 'rest_framework/horizontal/textarea.html'.
Traceback (most recent call last):
  File "/usr/local/lib/python3.6/site-packages/django/template/base.py", line 829, in _resolve_lookup
    current = current[bit]
KeyError: 'placeholder'

During handling of the above exception, another exception occurred:

Traceback (most recent call last):
  File "/usr/local/lib/python3.6/site-packages/django/template/base.py", line 837, in _resolve_lookup
    current = getattr(current, bit)
AttributeError: 'dict' object has no attribute 'placeholder'

During handling of the above exception, another exception occurred:

Traceback (most recent call last):
  File "/usr/local/lib/python3.6/site-packages/django/template/base.py", line 843, in _resolve_lookup
    current = current[int(bit)]
ValueError: invalid literal for int() with base 10: 'placeholder'

During handling of the above exception, another exception occurred:

Traceback (most recent call last):
  File "/usr/local/lib/python3.6/site-packages/django/template/base.py", line 850, in _resolve_lookup
    (bit, current))  # missing attribute
django.template.base.VariableDoesNotExist: Failed lookup for key [placeholder] in {'base_template': 'textarea.html', 'input_type': 'text', 'template_pack': 'rest_framework/horizontal', 'renderer': <rest_framework.renderers.HTMLFormRenderer object at 0x7f750809ee80>}
Exception while resolving variable 'rows' in template 'rest_framework/horizontal/textarea.html'.
Traceback (most recent call last):
  File "/usr/local/lib/python3.6/site-packages/django/template/base.py", line 829, in _resolve_lookup
    current = current[bit]
KeyError: 'rows'

During handling of the above exception, another exception occurred:

Traceback (most recent call last):
  File "/usr/local/lib/python3.6/site-packages/django/template/base.py", line 837, in _resolve_lookup
    current = getattr(current, bit)
AttributeError: 'dict' object has no attribute 'rows'

During handling of the above exception, another exception occurred:

Traceback (most recent call last):
  File "/usr/local/lib/python3.6/site-packages/django/template/base.py", line 843, in _resolve_lookup
    current = current[int(bit)]
ValueError: invalid literal for int() with base 10: 'rows'

During handling of the above exception, another exception occurred:

Traceback (most recent call last):
  File "/usr/local/lib/python3.6/site-packages/django/template/base.py", line 850, in _resolve_lookup
    (bit, current))  # missing attribute
django.template.base.VariableDoesNotExist: Failed lookup for key [rows] in {'base_template': 'textarea.html', 'input_type': 'text', 'template_pack': 'rest_framework/horizontal', 'renderer': <rest_framework.renderers.HTMLFormRenderer object at 0x7f750809ee80>}
"GET /api/v1/deploys/1/ HTTP/1.1" 200 10200
"GET /api/v1/deploys/1/ HTTP/1.1" 200 10200
(0.000) SET SESSION TRANSACTION ISOLATION LEVEL READ COMMITTED; args=None
(0.001) SELECT `django_session`.`session_key`, `django_session`.`session_data`, `django_session`.`expire_date` FROM `django_session` WHERE (`django_session`.`expire_date` > '2019-01-05 21:04:26.399247' AND `django_session`.`session_key` = 'h9tkpwnc85p71oh60fjq1kmxy4nqdlti'); args=('2019-01-05 21:04:26.399247', 'h9tkpwnc85p71oh60fjq1kmxy4nqdlti')
(0.001) SELECT `auth_user`.`id`, `auth_user`.`password`, `auth_user`.`last_login`, `auth_user`.`is_superuser`, `auth_user`.`username`, `auth_user`.`first_name`, `auth_user`.`last_name`, `auth_user`.`email`, `auth_user`.`is_staff`, `auth_user`.`is_active`, `auth_user`.`date_joined` FROM `auth_user` WHERE `auth_user`.`id` = 1; args=(1,)
(0.001) SELECT `deployer_deployer`.`id`, `deployer_deployer`.`queue_id`, `deployer_deployer`.`url` FROM `deployer_deployer` WHERE `deployer_deployer`.`id` = 1; args=(1,)
Exception while resolving variable 'hide_label' in template 'rest_framework/horizontal/input.html'.
Traceback (most recent call last):
  File "/usr/local/lib/python3.6/site-packages/django/template/base.py", line 829, in _resolve_lookup
    current = current[bit]
KeyError: 'hide_label'

During handling of the above exception, another exception occurred:

Traceback (most recent call last):
  File "/usr/local/lib/python3.6/site-packages/django/template/base.py", line 837, in _resolve_lookup
    current = getattr(current, bit)
AttributeError: 'dict' object has no attribute 'hide_label'

During handling of the above exception, another exception occurred:

Traceback (most recent call last):
  File "/usr/local/lib/python3.6/site-packages/django/template/base.py", line 843, in _resolve_lookup
    current = current[int(bit)]
ValueError: invalid literal for int() with base 10: 'hide_label'

During handling of the above exception, another exception occurred:

Traceback (most recent call last):
  File "/usr/local/lib/python3.6/site-packages/django/template/base.py", line 850, in _resolve_lookup
    (bit, current))  # missing attribute
django.template.base.VariableDoesNotExist: Failed lookup for key [hide_label] in {'base_template': 'input.html', 'input_type': 'text', 'template_pack': 'rest_framework/horizontal', 'renderer': <rest_framework.renderers.HTMLFormRenderer object at 0x7f75081278d0>}
Exception while resolving variable 'placeholder' in template 'rest_framework/horizontal/input.html'.
Traceback (most recent call last):
  File "/usr/local/lib/python3.6/site-packages/django/template/base.py", line 829, in _resolve_lookup
    current = current[bit]
KeyError: 'placeholder'

During handling of the above exception, another exception occurred:

Traceback (most recent call last):
  File "/usr/local/lib/python3.6/site-packages/django/template/base.py", line 837, in _resolve_lookup
    current = getattr(current, bit)
AttributeError: 'dict' object has no attribute 'placeholder'

During handling of the above exception, another exception occurred:

Traceback (most recent call last):
  File "/usr/local/lib/python3.6/site-packages/django/template/base.py", line 843, in _resolve_lookup
    current = current[int(bit)]
ValueError: invalid literal for int() with base 10: 'placeholder'

During handling of the above exception, another exception occurred:

Traceback (most recent call last):
  File "/usr/local/lib/python3.6/site-packages/django/template/base.py", line 850, in _resolve_lookup
    (bit, current))  # missing attribute
django.template.base.VariableDoesNotExist: Failed lookup for key [placeholder] in {'base_template': 'input.html', 'input_type': 'text', 'template_pack': 'rest_framework/horizontal', 'renderer': <rest_framework.renderers.HTMLFormRenderer object at 0x7f75081278d0>}
Exception while resolving variable 'autofocus' in template 'rest_framework/horizontal/input.html'.
Traceback (most recent call last):
  File "/usr/local/lib/python3.6/site-packages/django/template/base.py", line 829, in _resolve_lookup
    current = current[bit]
KeyError: 'autofocus'

During handling of the above exception, another exception occurred:

Traceback (most recent call last):
  File "/usr/local/lib/python3.6/site-packages/django/template/base.py", line 837, in _resolve_lookup
    current = getattr(current, bit)
AttributeError: 'dict' object has no attribute 'autofocus'

During handling of the above exception, another exception occurred:

Traceback (most recent call last):
  File "/usr/local/lib/python3.6/site-packages/django/template/base.py", line 843, in _resolve_lookup
    current = current[int(bit)]
ValueError: invalid literal for int() with base 10: 'autofocus'

During handling of the above exception, another exception occurred:

Traceback (most recent call last):
  File "/usr/local/lib/python3.6/site-packages/django/template/base.py", line 850, in _resolve_lookup
    (bit, current))  # missing attribute
django.template.base.VariableDoesNotExist: Failed lookup for key [autofocus] in {'base_template': 'input.html', 'input_type': 'text', 'template_pack': 'rest_framework/horizontal', 'renderer': <rest_framework.renderers.HTMLFormRenderer object at 0x7f75081278d0>}
Exception while resolving variable 'hide_label' in template 'rest_framework/horizontal/textarea.html'.
Traceback (most recent call last):
  File "/usr/local/lib/python3.6/site-packages/django/template/base.py", line 829, in _resolve_lookup
    current = current[bit]
KeyError: 'hide_label'

During handling of the above exception, another exception occurred:

Traceback (most recent call last):
  File "/usr/local/lib/python3.6/site-packages/django/template/base.py", line 837, in _resolve_lookup
    current = getattr(current, bit)
AttributeError: 'dict' object has no attribute 'hide_label'

During handling of the above exception, another exception occurred:

Traceback (most recent call last):
  File "/usr/local/lib/python3.6/site-packages/django/template/base.py", line 843, in _resolve_lookup
    current = current[int(bit)]
ValueError: invalid literal for int() with base 10: 'hide_label'

During handling of the above exception, another exception occurred:

Traceback (most recent call last):
  File "/usr/local/lib/python3.6/site-packages/django/template/base.py", line 850, in _resolve_lookup
    (bit, current))  # missing attribute
django.template.base.VariableDoesNotExist: Failed lookup for key [hide_label] in {'base_template': 'textarea.html', 'input_type': 'text', 'template_pack': 'rest_framework/horizontal', 'renderer': <rest_framework.renderers.HTMLFormRenderer object at 0x7f75081278d0>}
Exception while resolving variable 'placeholder' in template 'rest_framework/horizontal/textarea.html'.
Traceback (most recent call last):
  File "/usr/local/lib/python3.6/site-packages/django/template/base.py", line 829, in _resolve_lookup
    current = current[bit]
KeyError: 'placeholder'

During handling of the above exception, another exception occurred:

Traceback (most recent call last):
  File "/usr/local/lib/python3.6/site-packages/django/template/base.py", line 837, in _resolve_lookup
    current = getattr(current, bit)
AttributeError: 'dict' object has no attribute 'placeholder'

During handling of the above exception, another exception occurred:

Traceback (most recent call last):
  File "/usr/local/lib/python3.6/site-packages/django/template/base.py", line 843, in _resolve_lookup
    current = current[int(bit)]
ValueError: invalid literal for int() with base 10: 'placeholder'

During handling of the above exception, another exception occurred:

Traceback (most recent call last):
  File "/usr/local/lib/python3.6/site-packages/django/template/base.py", line 850, in _resolve_lookup
    (bit, current))  # missing attribute
django.template.base.VariableDoesNotExist: Failed lookup for key [placeholder] in {'base_template': 'textarea.html', 'input_type': 'text', 'template_pack': 'rest_framework/horizontal', 'renderer': <rest_framework.renderers.HTMLFormRenderer object at 0x7f75081278d0>}
Exception while resolving variable 'rows' in template 'rest_framework/horizontal/textarea.html'.
Traceback (most recent call last):
  File "/usr/local/lib/python3.6/site-packages/django/template/base.py", line 829, in _resolve_lookup
    current = current[bit]
KeyError: 'rows'

During handling of the above exception, another exception occurred:

Traceback (most recent call last):
  File "/usr/local/lib/python3.6/site-packages/django/template/base.py", line 837, in _resolve_lookup
    current = getattr(current, bit)
AttributeError: 'dict' object has no attribute 'rows'

During handling of the above exception, another exception occurred:

Traceback (most recent call last):
  File "/usr/local/lib/python3.6/site-packages/django/template/base.py", line 843, in _resolve_lookup
    current = current[int(bit)]
ValueError: invalid literal for int() with base 10: 'rows'

During handling of the above exception, another exception occurred:

Traceback (most recent call last):
  File "/usr/local/lib/python3.6/site-packages/django/template/base.py", line 850, in _resolve_lookup
    (bit, current))  # missing attribute
django.template.base.VariableDoesNotExist: Failed lookup for key [rows] in {'base_template': 'textarea.html', 'input_type': 'text', 'template_pack': 'rest_framework/horizontal', 'renderer': <rest_framework.renderers.HTMLFormRenderer object at 0x7f75081278d0>}
"GET /api/v1/deploys/1/ HTTP/1.1" 200 10200
"GET /api/v1/deploys/1/ HTTP/1.1" 200 10200
"GET /api/v1/deploys/1/ HTTP/1.1" 200 10200
"GET /static/rest_framework/css/bootstrap-tweaks.css HTTP/1.1" 304 0
"GET /static/rest_framework/css/bootstrap.min.css HTTP/1.1" 304 0
"GET /static/rest_framework/css/prettify.css HTTP/1.1" 304 0
"GET /static/rest_framework/css/default.css HTTP/1.1" 304 0
"GET /static/rest_framework/js/ajax-form.js HTTP/1.1" 304 0
"GET /static/rest_framework/js/jquery-3.3.1.min.js HTTP/1.1" 304 0
"GET /static/rest_framework/js/csrf.js HTTP/1.1" 304 0
"GET /static/rest_framework/js/bootstrap.min.js HTTP/1.1" 304 0
"GET /static/rest_framework/js/prettify-min.js HTTP/1.1" 304 0
"GET /static/rest_framework/js/default.js HTTP/1.1" 304 0
"GET /static/rest_framework/img/grid.png HTTP/1.1" 304 0
"GET /api/v1/deploys/1/ HTTP/1.1" 200 10200
"GET /api/v1/deploys/1/ HTTP/1.1" 200 10200
"GET /api/v1/deploys/1/ HTTP/1.1" 200 10200
"GET /api/v1/deploys/1/ HTTP/1.1" 200 10200
"GET /static/rest_framework/css/bootstrap-tweaks.css HTTP/1.1" 304 0
"GET /static/rest_framework/css/prettify.css HTTP/1.1" 304 0
"GET /static/rest_framework/css/default.css HTTP/1.1" 304 0
"GET /static/rest_framework/css/bootstrap.min.css HTTP/1.1" 304 0
"GET /static/rest_framework/js/jquery-3.3.1.min.js HTTP/1.1" 304 0
"GET /static/rest_framework/js/ajax-form.js HTTP/1.1" 304 0
"GET /static/rest_framework/js/csrf.js HTTP/1.1" 304 0
"GET /static/rest_framework/js/bootstrap.min.js HTTP/1.1" 304 0
"GET /static/rest_framework/js/prettify-min.js HTTP/1.1" 304 0
"GET /static/rest_framework/js/default.js HTTP/1.1" 304 0
"GET /static/rest_framework/img/grid.png HTTP/1.1" 304 0
Internal Server Error: /api/v1/deploys/1/
Traceback (most recent call last):
  File "/usr/local/lib/python3.6/site-packages/django/core/handlers/exception.py", line 34, in inner
    response = get_response(request)
  File "/usr/local/lib/python3.6/site-packages/django/core/handlers/base.py", line 126, in _get_response
    response = self.process_exception_by_middleware(e, request)
  File "/usr/local/lib/python3.6/site-packages/django/core/handlers/base.py", line 124, in _get_response
    response = wrapped_callback(request, *callback_args, **callback_kwargs)
  File "/usr/local/lib/python3.6/site-packages/django/views/decorators/csrf.py", line 54, in wrapped_view
    return view_func(*args, **kwargs)
  File "/usr/local/lib/python3.6/site-packages/django/views/generic/base.py", line 68, in view
    return self.dispatch(request, *args, **kwargs)
  File "/usr/local/lib/python3.6/site-packages/rest_framework/views.py", line 495, in dispatch
    response = self.handle_exception(exc)
  File "/usr/local/lib/python3.6/site-packages/rest_framework/views.py", line 455, in handle_exception
    self.raise_uncaught_exception(exc)
  File "/usr/local/lib/python3.6/site-packages/rest_framework/views.py", line 492, in dispatch
    response = handler(request, *args, **kwargs)
  File "/app/api/views/api_view.py", line 17, in get
    test_task("receive get")
  File "/usr/local/lib/python3.6/site-packages/celery/local.py", line 191, in __call__
    return self._get_current_object()(*a, **kw)
  File "/usr/local/lib/python3.6/site-packages/celery/app/task.py", line 375, in __call__
    return self.run(*args, **kwargs)
  File "/app/deployer/tasks.py", line 14, in test_task
    deployer.save()
AttributeError: 'QuerySet' object has no attribute 'save'
"GET /api/v1/deploys/1/ HTTP/1.1" 500 95815
"GET /api/v1/deploys/1/ HTTP/1.1" 200 10185
"GET /static/rest_framework/css/bootstrap-tweaks.css HTTP/1.1" 304 0
"GET /static/rest_framework/css/bootstrap.min.css HTTP/1.1" 304 0
"GET /static/rest_framework/css/prettify.css HTTP/1.1" 304 0
"GET /static/rest_framework/js/jquery-3.3.1.min.js HTTP/1.1" 304 0
"GET /static/rest_framework/css/default.css HTTP/1.1" 304 0
"GET /static/rest_framework/js/ajax-form.js HTTP/1.1" 304 0
"GET /static/rest_framework/js/csrf.js HTTP/1.1" 304 0
"GET /static/rest_framework/js/bootstrap.min.js HTTP/1.1" 304 0
"GET /static/rest_framework/js/prettify-min.js HTTP/1.1" 304 0
"GET /static/rest_framework/js/default.js HTTP/1.1" 304 0
"GET /static/rest_framework/img/grid.png HTTP/1.1" 304 0
"GET /api/v1/deploys/1/ HTTP/1.1" 200 10185
"GET /api/v1/deploys/1/ HTTP/1.1" 200 10185
Internal Server Error: /api/v1/deploys/1/
Traceback (most recent call last):
  File "/usr/local/lib/python3.6/site-packages/django/core/handlers/exception.py", line 34, in inner
    response = get_response(request)
  File "/usr/local/lib/python3.6/site-packages/django/core/handlers/base.py", line 126, in _get_response
    response = self.process_exception_by_middleware(e, request)
  File "/usr/local/lib/python3.6/site-packages/django/core/handlers/base.py", line 124, in _get_response
    response = wrapped_callback(request, *callback_args, **callback_kwargs)
  File "/usr/local/lib/python3.6/site-packages/django/views/decorators/csrf.py", line 54, in wrapped_view
    return view_func(*args, **kwargs)
  File "/usr/local/lib/python3.6/site-packages/django/views/generic/base.py", line 68, in view
    return self.dispatch(request, *args, **kwargs)
  File "/usr/local/lib/python3.6/site-packages/rest_framework/views.py", line 495, in dispatch
    response = self.handle_exception(exc)
  File "/usr/local/lib/python3.6/site-packages/rest_framework/views.py", line 455, in handle_exception
    self.raise_uncaught_exception(exc)
  File "/usr/local/lib/python3.6/site-packages/rest_framework/views.py", line 492, in dispatch
    response = handler(request, *args, **kwargs)
  File "/app/api/views/api_view.py", line 17, in get
    test_task("receive get")
  File "/usr/local/lib/python3.6/site-packages/celery/local.py", line 191, in __call__
    return self._get_current_object()(*a, **kw)
  File "/usr/local/lib/python3.6/site-packages/celery/app/task.py", line 375, in __call__
    return self.run(*args, **kwargs)
  File "/app/deployer/tasks.py", line 13, in test_task
    holder = int(deployer.queue)
AttributeError: 'Deployer' object has no attribute 'queue'
"GET /api/v1/deploys/1/ HTTP/1.1" 500 96095
Internal Server Error: /api/v1/deploys/1/
Traceback (most recent call last):
  File "/usr/local/lib/python3.6/site-packages/django/core/handlers/exception.py", line 34, in inner
    response = get_response(request)
  File "/usr/local/lib/python3.6/site-packages/django/core/handlers/base.py", line 126, in _get_response
    response = self.process_exception_by_middleware(e, request)
  File "/usr/local/lib/python3.6/site-packages/django/core/handlers/base.py", line 124, in _get_response
    response = wrapped_callback(request, *callback_args, **callback_kwargs)
  File "/usr/local/lib/python3.6/site-packages/django/views/decorators/csrf.py", line 54, in wrapped_view
    return view_func(*args, **kwargs)
  File "/usr/local/lib/python3.6/site-packages/django/views/generic/base.py", line 68, in view
    return self.dispatch(request, *args, **kwargs)
  File "/usr/local/lib/python3.6/site-packages/rest_framework/views.py", line 495, in dispatch
    response = self.handle_exception(exc)
  File "/usr/local/lib/python3.6/site-packages/rest_framework/views.py", line 455, in handle_exception
    self.raise_uncaught_exception(exc)
  File "/usr/local/lib/python3.6/site-packages/rest_framework/views.py", line 492, in dispatch
    response = handler(request, *args, **kwargs)
  File "/app/api/views/api_view.py", line 17, in get
    test_task("receive get")
  File "/usr/local/lib/python3.6/site-packages/celery/local.py", line 191, in __call__
    return self._get_current_object()(*a, **kw)
  File "/usr/local/lib/python3.6/site-packages/celery/app/task.py", line 375, in __call__
    return self.run(*args, **kwargs)
  File "/app/deployer/tasks.py", line 13, in test_task
    holder = int(deployer.queue)
AttributeError: 'Deployer' object has no attribute 'queue'
"GET /api/v1/deploys/1/ HTTP/1.1" 500 96095
Internal Server Error: /api/v1/deploys/1/
Traceback (most recent call last):
  File "/usr/local/lib/python3.6/site-packages/django/core/handlers/exception.py", line 34, in inner
    response = get_response(request)
  File "/usr/local/lib/python3.6/site-packages/django/core/handlers/base.py", line 126, in _get_response
    response = self.process_exception_by_middleware(e, request)
  File "/usr/local/lib/python3.6/site-packages/django/core/handlers/base.py", line 124, in _get_response
    response = wrapped_callback(request, *callback_args, **callback_kwargs)
  File "/usr/local/lib/python3.6/site-packages/django/views/decorators/csrf.py", line 54, in wrapped_view
    return view_func(*args, **kwargs)
  File "/usr/local/lib/python3.6/site-packages/django/views/generic/base.py", line 68, in view
    return self.dispatch(request, *args, **kwargs)
  File "/usr/local/lib/python3.6/site-packages/rest_framework/views.py", line 495, in dispatch
    response = self.handle_exception(exc)
  File "/usr/local/lib/python3.6/site-packages/rest_framework/views.py", line 455, in handle_exception
    self.raise_uncaught_exception(exc)
  File "/usr/local/lib/python3.6/site-packages/rest_framework/views.py", line 492, in dispatch
    response = handler(request, *args, **kwargs)
  File "/app/api/views/api_view.py", line 17, in get
    test_task("receive get")
  File "/usr/local/lib/python3.6/site-packages/celery/local.py", line 191, in __call__
    return self._get_current_object()(*a, **kw)
  File "/usr/local/lib/python3.6/site-packages/celery/app/task.py", line 375, in __call__
    return self.run(*args, **kwargs)
  File "/app/deployer/tasks.py", line 14, in test_task
    deployer.queue_id += holder
TypeError: must be str, not int
"GET /api/v1/deploys/1/ HTTP/1.1" 500 95903
"GET /api/v1/deploys/1/ HTTP/1.1" 200 10185
"GET /static/rest_framework/css/bootstrap-tweaks.css HTTP/1.1" 304 0
"GET /static/rest_framework/css/bootstrap.min.css HTTP/1.1" 304 0
"GET /static/rest_framework/css/default.css HTTP/1.1" 304 0
"GET /static/rest_framework/css/prettify.css HTTP/1.1" 304 0
"GET /static/rest_framework/js/jquery-3.3.1.min.js HTTP/1.1" 304 0
"GET /static/rest_framework/js/ajax-form.js HTTP/1.1" 304 0
"GET /static/rest_framework/js/csrf.js HTTP/1.1" 304 0
"GET /static/rest_framework/js/bootstrap.min.js HTTP/1.1" 304 0
"GET /static/rest_framework/js/default.js HTTP/1.1" 304 0
"GET /static/rest_framework/js/prettify-min.js HTTP/1.1" 304 0
"GET /static/rest_framework/img/grid.png HTTP/1.1" 304 0
"GET /api/v1/deploys/1/ HTTP/1.1" 200 10185
"GET /api/v1/deploys/1/ HTTP/1.1" 200 10185
"GET /api/v1/deploys/1/ HTTP/1.1" 200 10185
"GET /api/v1/deploys/1/ HTTP/1.1" 200 10185
Internal Server Error: /api/v1/deploys/1/
Traceback (most recent call last):
  File "/usr/local/lib/python3.6/site-packages/django/core/handlers/exception.py", line 34, in inner
    response = get_response(request)
  File "/usr/local/lib/python3.6/site-packages/django/core/handlers/base.py", line 126, in _get_response
    response = self.process_exception_by_middleware(e, request)
  File "/usr/local/lib/python3.6/site-packages/django/core/handlers/base.py", line 124, in _get_response
    response = wrapped_callback(request, *callback_args, **callback_kwargs)
  File "/usr/local/lib/python3.6/site-packages/django/views/decorators/csrf.py", line 54, in wrapped_view
    return view_func(*args, **kwargs)
  File "/usr/local/lib/python3.6/site-packages/django/views/generic/base.py", line 68, in view
    return self.dispatch(request, *args, **kwargs)
  File "/usr/local/lib/python3.6/site-packages/rest_framework/views.py", line 495, in dispatch
    response = self.handle_exception(exc)
  File "/usr/local/lib/python3.6/site-packages/rest_framework/views.py", line 455, in handle_exception
    self.raise_uncaught_exception(exc)
  File "/usr/local/lib/python3.6/site-packages/rest_framework/views.py", line 492, in dispatch
    response = handler(request, *args, **kwargs)
  File "/app/api/views/api_view.py", line 17, in get
    test_task.delay("receive get")
  File "/usr/local/lib/python3.6/site-packages/celery/app/task.py", line 408, in delay
    return self.apply_async(args, kwargs)
  File "/usr/local/lib/python3.6/site-packages/celery/app/task.py", line 535, in apply_async
    **options
  File "/usr/local/lib/python3.6/site-packages/celery/app/base.py", line 741, in send_task
    with self.producer_or_acquire(producer) as P:
  File "/usr/local/lib/python3.6/site-packages/celery/utils/objects.py", line 86, in __enter__
    *self.fb_args, **self.fb_kwargs
  File "/usr/local/lib/python3.6/site-packages/kombu/resource.py", line 83, in acquire
    R = self.prepare(R)
  File "/usr/local/lib/python3.6/site-packages/kombu/pools.py", line 62, in prepare
    p = p()
  File "/usr/local/lib/python3.6/site-packages/kombu/utils/functional.py", line 203, in __call__
    return self.evaluate()
  File "/usr/local/lib/python3.6/site-packages/kombu/utils/functional.py", line 206, in evaluate
    return self._fun(*self._args, **self._kwargs)
  File "/usr/local/lib/python3.6/site-packages/kombu/pools.py", line 42, in create_producer
    conn = self._acquire_connection()
  File "/usr/local/lib/python3.6/site-packages/kombu/pools.py", line 39, in _acquire_connection
    return self.connections.acquire(block=True)
  File "/usr/local/lib/python3.6/site-packages/kombu/resource.py", line 83, in acquire
    R = self.prepare(R)
  File "/usr/local/lib/python3.6/site-packages/kombu/connection.py", line 948, in prepare
    resource = resource()
  File "/usr/local/lib/python3.6/site-packages/kombu/utils/functional.py", line 203, in __call__
    return self.evaluate()
  File "/usr/local/lib/python3.6/site-packages/kombu/utils/functional.py", line 206, in evaluate
    return self._fun(*self._args, **self._kwargs)
  File "/usr/local/lib/python3.6/site-packages/kombu/connection.py", line 920, in new
    return self.connection.clone()
  File "/usr/local/lib/python3.6/site-packages/kombu/connection.py", line 587, in clone
    return self.__class__(**dict(self._info(resolve=False), **kwargs))
  File "/usr/local/lib/python3.6/site-packages/kombu/connection.py", line 597, in _info
    D = self.transport.default_connection_params
  File "/usr/local/lib/python3.6/site-packages/kombu/connection.py", line 844, in transport
    self._transport = self.create_transport()
  File "/usr/local/lib/python3.6/site-packages/kombu/connection.py", line 576, in create_transport
    return self.get_transport_cls()(client=self)
  File "/usr/local/lib/python3.6/site-packages/kombu/transport/redis.py", line 1016, in __init__
    raise ImportError('Missing redis library (pip install redis)')
ImportError: Missing redis library (pip install redis)
"GET /api/v1/deploys/1/ HTTP/1.1" 500 174692
Internal Server Error: /api/v1/deploys/1/
Traceback (most recent call last):
  File "/usr/local/lib/python3.6/site-packages/django/core/handlers/exception.py", line 34, in inner
    response = get_response(request)
  File "/usr/local/lib/python3.6/site-packages/django/core/handlers/base.py", line 126, in _get_response
    response = self.process_exception_by_middleware(e, request)
  File "/usr/local/lib/python3.6/site-packages/django/core/handlers/base.py", line 124, in _get_response
    response = wrapped_callback(request, *callback_args, **callback_kwargs)
  File "/usr/local/lib/python3.6/site-packages/django/views/decorators/csrf.py", line 54, in wrapped_view
    return view_func(*args, **kwargs)
  File "/usr/local/lib/python3.6/site-packages/django/views/generic/base.py", line 68, in view
    return self.dispatch(request, *args, **kwargs)
  File "/usr/local/lib/python3.6/site-packages/rest_framework/views.py", line 495, in dispatch
    response = self.handle_exception(exc)
  File "/usr/local/lib/python3.6/site-packages/rest_framework/views.py", line 455, in handle_exception
    self.raise_uncaught_exception(exc)
  File "/usr/local/lib/python3.6/site-packages/rest_framework/views.py", line 492, in dispatch
    response = handler(request, *args, **kwargs)
  File "/app/api/views/api_view.py", line 17, in get
    test_task.delay("receive get")
  File "/usr/local/lib/python3.6/site-packages/celery/app/task.py", line 408, in delay
    return self.apply_async(args, kwargs)
  File "/usr/local/lib/python3.6/site-packages/celery/app/task.py", line 535, in apply_async
    **options
  File "/usr/local/lib/python3.6/site-packages/celery/app/base.py", line 741, in send_task
    with self.producer_or_acquire(producer) as P:
  File "/usr/local/lib/python3.6/site-packages/celery/utils/objects.py", line 86, in __enter__
    *self.fb_args, **self.fb_kwargs
  File "/usr/local/lib/python3.6/site-packages/kombu/resource.py", line 83, in acquire
    R = self.prepare(R)
  File "/usr/local/lib/python3.6/site-packages/kombu/pools.py", line 62, in prepare
    p = p()
  File "/usr/local/lib/python3.6/site-packages/kombu/utils/functional.py", line 203, in __call__
    return self.evaluate()
  File "/usr/local/lib/python3.6/site-packages/kombu/utils/functional.py", line 206, in evaluate
    return self._fun(*self._args, **self._kwargs)
  File "/usr/local/lib/python3.6/site-packages/kombu/pools.py", line 42, in create_producer
    conn = self._acquire_connection()
  File "/usr/local/lib/python3.6/site-packages/kombu/pools.py", line 39, in _acquire_connection
    return self.connections.acquire(block=True)
  File "/usr/local/lib/python3.6/site-packages/kombu/resource.py", line 83, in acquire
    R = self.prepare(R)
  File "/usr/local/lib/python3.6/site-packages/kombu/connection.py", line 948, in prepare
    resource = resource()
  File "/usr/local/lib/python3.6/site-packages/kombu/utils/functional.py", line 203, in __call__
    return self.evaluate()
  File "/usr/local/lib/python3.6/site-packages/kombu/utils/functional.py", line 206, in evaluate
    return self._fun(*self._args, **self._kwargs)
  File "/usr/local/lib/python3.6/site-packages/kombu/connection.py", line 920, in new
    return self.connection.clone()
  File "/usr/local/lib/python3.6/site-packages/kombu/connection.py", line 587, in clone
    return self.__class__(**dict(self._info(resolve=False), **kwargs))
  File "/usr/local/lib/python3.6/site-packages/kombu/connection.py", line 597, in _info
    D = self.transport.default_connection_params
  File "/usr/local/lib/python3.6/site-packages/kombu/connection.py", line 844, in transport
    self._transport = self.create_transport()
  File "/usr/local/lib/python3.6/site-packages/kombu/connection.py", line 576, in create_transport
    return self.get_transport_cls()(client=self)
  File "/usr/local/lib/python3.6/site-packages/kombu/transport/redis.py", line 1016, in __init__
    raise ImportError('Missing redis library (pip install redis)')
ImportError: Missing redis library (pip install redis)
"GET /api/v1/deploys/1/ HTTP/1.1" 500 174683
Internal Server Error: /api/v1/deploys/1/
Traceback (most recent call last):
  File "/usr/local/lib/python3.6/site-packages/django/core/handlers/exception.py", line 34, in inner
    response = get_response(request)
  File "/usr/local/lib/python3.6/site-packages/django/core/handlers/base.py", line 126, in _get_response
    response = self.process_exception_by_middleware(e, request)
  File "/usr/local/lib/python3.6/site-packages/django/core/handlers/base.py", line 124, in _get_response
    response = wrapped_callback(request, *callback_args, **callback_kwargs)
  File "/usr/local/lib/python3.6/site-packages/django/views/decorators/csrf.py", line 54, in wrapped_view
    return view_func(*args, **kwargs)
  File "/usr/local/lib/python3.6/site-packages/django/views/generic/base.py", line 68, in view
    return self.dispatch(request, *args, **kwargs)
  File "/usr/local/lib/python3.6/site-packages/rest_framework/views.py", line 495, in dispatch
    response = self.handle_exception(exc)
  File "/usr/local/lib/python3.6/site-packages/rest_framework/views.py", line 455, in handle_exception
    self.raise_uncaught_exception(exc)
  File "/usr/local/lib/python3.6/site-packages/rest_framework/views.py", line 492, in dispatch
    response = handler(request, *args, **kwargs)
  File "/app/api/views/api_view.py", line 17, in get
    test_task.delay("receive get")
  File "/usr/local/lib/python3.6/site-packages/celery/app/task.py", line 408, in delay
    return self.apply_async(args, kwargs)
  File "/usr/local/lib/python3.6/site-packages/celery/app/task.py", line 535, in apply_async
    **options
  File "/usr/local/lib/python3.6/site-packages/celery/app/base.py", line 741, in send_task
    with self.producer_or_acquire(producer) as P:
  File "/usr/local/lib/python3.6/site-packages/celery/utils/objects.py", line 86, in __enter__
    *self.fb_args, **self.fb_kwargs
  File "/usr/local/lib/python3.6/site-packages/kombu/resource.py", line 83, in acquire
    R = self.prepare(R)
  File "/usr/local/lib/python3.6/site-packages/kombu/pools.py", line 62, in prepare
    p = p()
  File "/usr/local/lib/python3.6/site-packages/kombu/utils/functional.py", line 203, in __call__
    return self.evaluate()
  File "/usr/local/lib/python3.6/site-packages/kombu/utils/functional.py", line 206, in evaluate
    return self._fun(*self._args, **self._kwargs)
  File "/usr/local/lib/python3.6/site-packages/kombu/pools.py", line 42, in create_producer
    conn = self._acquire_connection()
  File "/usr/local/lib/python3.6/site-packages/kombu/pools.py", line 39, in _acquire_connection
    return self.connections.acquire(block=True)
  File "/usr/local/lib/python3.6/site-packages/kombu/resource.py", line 83, in acquire
    R = self.prepare(R)
  File "/usr/local/lib/python3.6/site-packages/kombu/connection.py", line 948, in prepare
    resource = resource()
  File "/usr/local/lib/python3.6/site-packages/kombu/utils/functional.py", line 203, in __call__
    return self.evaluate()
  File "/usr/local/lib/python3.6/site-packages/kombu/utils/functional.py", line 206, in evaluate
    return self._fun(*self._args, **self._kwargs)
  File "/usr/local/lib/python3.6/site-packages/kombu/connection.py", line 920, in new
    return self.connection.clone()
  File "/usr/local/lib/python3.6/site-packages/kombu/connection.py", line 587, in clone
    return self.__class__(**dict(self._info(resolve=False), **kwargs))
  File "/usr/local/lib/python3.6/site-packages/kombu/connection.py", line 597, in _info
    D = self.transport.default_connection_params
  File "/usr/local/lib/python3.6/site-packages/kombu/connection.py", line 844, in transport
    self._transport = self.create_transport()
  File "/usr/local/lib/python3.6/site-packages/kombu/connection.py", line 576, in create_transport
    return self.get_transport_cls()(client=self)
  File "/usr/local/lib/python3.6/site-packages/kombu/transport/redis.py", line 1016, in __init__
    raise ImportError('Missing redis library (pip install redis)')
ImportError: Missing redis library (pip install redis)
"GET /api/v1/deploys/1/ HTTP/1.1" 500 174683
Internal Server Error: /api/v1/deploys/1/
Traceback (most recent call last):
  File "/usr/local/lib/python3.6/site-packages/django/core/handlers/exception.py", line 34, in inner
    response = get_response(request)
  File "/usr/local/lib/python3.6/site-packages/django/core/handlers/base.py", line 126, in _get_response
    response = self.process_exception_by_middleware(e, request)
  File "/usr/local/lib/python3.6/site-packages/django/core/handlers/base.py", line 124, in _get_response
    response = wrapped_callback(request, *callback_args, **callback_kwargs)
  File "/usr/local/lib/python3.6/site-packages/django/views/decorators/csrf.py", line 54, in wrapped_view
    return view_func(*args, **kwargs)
  File "/usr/local/lib/python3.6/site-packages/django/views/generic/base.py", line 68, in view
    return self.dispatch(request, *args, **kwargs)
  File "/usr/local/lib/python3.6/site-packages/rest_framework/views.py", line 495, in dispatch
    response = self.handle_exception(exc)
  File "/usr/local/lib/python3.6/site-packages/rest_framework/views.py", line 455, in handle_exception
    self.raise_uncaught_exception(exc)
  File "/usr/local/lib/python3.6/site-packages/rest_framework/views.py", line 492, in dispatch
    response = handler(request, *args, **kwargs)
  File "/app/api/views/api_view.py", line 17, in get
    test_task.delay("receive get")
  File "/usr/local/lib/python3.6/site-packages/celery/app/task.py", line 408, in delay
    return self.apply_async(args, kwargs)
  File "/usr/local/lib/python3.6/site-packages/celery/app/task.py", line 535, in apply_async
    **options
  File "/usr/local/lib/python3.6/site-packages/celery/app/base.py", line 741, in send_task
    with self.producer_or_acquire(producer) as P:
  File "/usr/local/lib/python3.6/site-packages/celery/utils/objects.py", line 86, in __enter__
    *self.fb_args, **self.fb_kwargs
  File "/usr/local/lib/python3.6/site-packages/kombu/resource.py", line 83, in acquire
    R = self.prepare(R)
  File "/usr/local/lib/python3.6/site-packages/kombu/pools.py", line 62, in prepare
    p = p()
  File "/usr/local/lib/python3.6/site-packages/kombu/utils/functional.py", line 203, in __call__
    return self.evaluate()
  File "/usr/local/lib/python3.6/site-packages/kombu/utils/functional.py", line 206, in evaluate
    return self._fun(*self._args, **self._kwargs)
  File "/usr/local/lib/python3.6/site-packages/kombu/pools.py", line 42, in create_producer
    conn = self._acquire_connection()
  File "/usr/local/lib/python3.6/site-packages/kombu/pools.py", line 39, in _acquire_connection
    return self.connections.acquire(block=True)
  File "/usr/local/lib/python3.6/site-packages/kombu/resource.py", line 83, in acquire
    R = self.prepare(R)
  File "/usr/local/lib/python3.6/site-packages/kombu/connection.py", line 948, in prepare
    resource = resource()
  File "/usr/local/lib/python3.6/site-packages/kombu/utils/functional.py", line 203, in __call__
    return self.evaluate()
  File "/usr/local/lib/python3.6/site-packages/kombu/utils/functional.py", line 206, in evaluate
    return self._fun(*self._args, **self._kwargs)
  File "/usr/local/lib/python3.6/site-packages/kombu/connection.py", line 920, in new
    return self.connection.clone()
  File "/usr/local/lib/python3.6/site-packages/kombu/connection.py", line 587, in clone
    return self.__class__(**dict(self._info(resolve=False), **kwargs))
  File "/usr/local/lib/python3.6/site-packages/kombu/connection.py", line 597, in _info
    D = self.transport.default_connection_params
  File "/usr/local/lib/python3.6/site-packages/kombu/connection.py", line 844, in transport
    self._transport = self.create_transport()
  File "/usr/local/lib/python3.6/site-packages/kombu/connection.py", line 576, in create_transport
    return self.get_transport_cls()(client=self)
  File "/usr/local/lib/python3.6/site-packages/kombu/transport/redis.py", line 1016, in __init__
    raise ImportError('Missing redis library (pip install redis)')
ImportError: Missing redis library (pip install redis)
"GET /api/v1/deploys/1/ HTTP/1.1" 500 174683
"GET /api/v1/deploys/1/ HTTP/1.1" 200 10185
"GET /static/rest_framework/css/bootstrap-tweaks.css HTTP/1.1" 200 3385
"GET /static/rest_framework/css/prettify.css HTTP/1.1" 200 817
"GET /static/rest_framework/css/default.css HTTP/1.1" 200 1131
"GET /static/rest_framework/js/csrf.js HTTP/1.1" 200 1735
"GET /static/rest_framework/js/ajax-form.js HTTP/1.1" 200 3597
"GET /static/rest_framework/js/default.js HTTP/1.1" 200 1268
"GET /static/rest_framework/css/bootstrap.min.css HTTP/1.1" 200 121200
"GET /static/rest_framework/js/jquery-3.3.1.min.js HTTP/1.1" 200 86927
"GET /static/rest_framework/js/bootstrap.min.js HTTP/1.1" 200 37045
"GET /static/rest_framework/js/prettify-min.js HTTP/1.1" 200 13632
"GET /static/rest_framework/img/grid.png HTTP/1.1" 200 1458
"GET /api/v1/deploys/1/ HTTP/1.1" 200 10188
"GET /static/rest_framework/css/bootstrap-tweaks.css HTTP/1.1" 304 0
"GET /static/rest_framework/css/bootstrap.min.css HTTP/1.1" 304 0
"GET /static/rest_framework/css/prettify.css HTTP/1.1" 304 0
"GET /static/rest_framework/css/default.css HTTP/1.1" 304 0
"GET /static/rest_framework/js/jquery-3.3.1.min.js HTTP/1.1" 304 0
"GET /static/rest_framework/js/ajax-form.js HTTP/1.1" 304 0
"GET /static/rest_framework/js/prettify-min.js HTTP/1.1" 304 0
"GET /static/rest_framework/js/csrf.js HTTP/1.1" 304 0
"GET /static/rest_framework/js/bootstrap.min.js HTTP/1.1" 304 0
"GET /static/rest_framework/js/default.js HTTP/1.1" 304 0
"GET /static/rest_framework/img/grid.png HTTP/1.1" 304 0
"GET /api/v1/deploys/1/ HTTP/1.1" 200 10188
"GET /api/v1/deploys/1/ HTTP/1.1" 200 10188
"GET /static/rest_framework/css/bootstrap.min.css HTTP/1.1" 304 0
"GET /static/rest_framework/css/bootstrap-tweaks.css HTTP/1.1" 304 0
"GET /static/rest_framework/css/prettify.css HTTP/1.1" 304 0
"GET /static/rest_framework/js/ajax-form.js HTTP/1.1" 304 0
"GET /static/rest_framework/css/default.css HTTP/1.1" 304 0
"GET /static/rest_framework/js/jquery-3.3.1.min.js HTTP/1.1" 304 0
"GET /static/rest_framework/js/csrf.js HTTP/1.1" 304 0
"GET /static/rest_framework/js/bootstrap.min.js HTTP/1.1" 304 0
"GET /static/rest_framework/js/prettify-min.js HTTP/1.1" 304 0
"GET /static/rest_framework/js/default.js HTTP/1.1" 304 0
"GET /static/rest_framework/img/grid.png HTTP/1.1" 304 0
"GET /api/v1/deploys/1/ HTTP/1.1" 200 10188
"GET /api/v1/deploys/1/ HTTP/1.1" 200 10188
"GET /api/v1/deploys/1/ HTTP/1.1" 200 10188
"GET /static/rest_framework/css/bootstrap.min.css HTTP/1.1" 304 0
"GET /static/rest_framework/css/prettify.css HTTP/1.1" 304 0
"GET /static/rest_framework/css/bootstrap-tweaks.css HTTP/1.1" 304 0
"GET /static/rest_framework/css/default.css HTTP/1.1" 304 0
"GET /static/rest_framework/js/jquery-3.3.1.min.js HTTP/1.1" 304 0
"GET /static/rest_framework/js/ajax-form.js HTTP/1.1" 304 0
"GET /static/rest_framework/js/csrf.js HTTP/1.1" 304 0
"GET /static/rest_framework/js/bootstrap.min.js HTTP/1.1" 304 0
"GET /static/rest_framework/js/prettify-min.js HTTP/1.1" 304 0
"GET /static/rest_framework/js/default.js HTTP/1.1" 304 0
"GET /static/rest_framework/img/grid.png HTTP/1.1" 304 0
"GET /api/v1/deploys/1/ HTTP/1.1" 200 10188
"GET /api/v1/deploys/1/ HTTP/1.1" 200 10188
"GET /api/v1/deploys/1/ HTTP/1.1" 200 10188
"GET /static/rest_framework/css/bootstrap-tweaks.css HTTP/1.1" 304 0
"GET /static/rest_framework/css/bootstrap.min.css HTTP/1.1" 304 0
"GET /static/rest_framework/css/default.css HTTP/1.1" 304 0
"GET /static/rest_framework/css/prettify.css HTTP/1.1" 304 0
"GET /static/rest_framework/js/jquery-3.3.1.min.js HTTP/1.1" 304 0
"GET /static/rest_framework/js/ajax-form.js HTTP/1.1" 304 0
"GET /static/rest_framework/js/csrf.js HTTP/1.1" 304 0
"GET /static/rest_framework/js/bootstrap.min.js HTTP/1.1" 304 0
"GET /static/rest_framework/js/default.js HTTP/1.1" 304 0
"GET /static/rest_framework/js/prettify-min.js HTTP/1.1" 304 0
"GET /static/rest_framework/img/grid.png HTTP/1.1" 304 0
Internal Server Error: /api/v1/deploys/1/
Traceback (most recent call last):
  File "/usr/local/lib/python3.6/site-packages/django/core/handlers/exception.py", line 34, in inner
    response = get_response(request)
  File "/usr/local/lib/python3.6/site-packages/django/core/handlers/base.py", line 126, in _get_response
    response = self.process_exception_by_middleware(e, request)
  File "/usr/local/lib/python3.6/site-packages/django/core/handlers/base.py", line 124, in _get_response
    response = wrapped_callback(request, *callback_args, **callback_kwargs)
  File "/usr/local/lib/python3.6/site-packages/django/views/decorators/csrf.py", line 54, in wrapped_view
    return view_func(*args, **kwargs)
  File "/usr/local/lib/python3.6/site-packages/django/views/generic/base.py", line 68, in view
    return self.dispatch(request, *args, **kwargs)
  File "/usr/local/lib/python3.6/site-packages/rest_framework/views.py", line 495, in dispatch
    response = self.handle_exception(exc)
  File "/usr/local/lib/python3.6/site-packages/rest_framework/views.py", line 455, in handle_exception
    self.raise_uncaught_exception(exc)
  File "/usr/local/lib/python3.6/site-packages/rest_framework/views.py", line 492, in dispatch
    response = handler(request, *args, **kwargs)
  File "/app/api/views/api_view.py", line 17, in get
    test_task.apply_async(7, countdown=3)
  File "/usr/local/lib/python3.6/site-packages/celery/app/task.py", line 513, in apply_async
    check_arguments(*(args or ()), **(kwargs or {}))
TypeError: test_task() argument after * must be an iterable, not int
"GET /api/v1/deploys/1/ HTTP/1.1" 500 89947
Internal Server Error: /api/v1/deploys/1/
Traceback (most recent call last):
  File "/usr/local/lib/python3.6/site-packages/django/core/handlers/exception.py", line 34, in inner
    response = get_response(request)
  File "/usr/local/lib/python3.6/site-packages/django/core/handlers/base.py", line 126, in _get_response
    response = self.process_exception_by_middleware(e, request)
  File "/usr/local/lib/python3.6/site-packages/django/core/handlers/base.py", line 124, in _get_response
    response = wrapped_callback(request, *callback_args, **callback_kwargs)
  File "/usr/local/lib/python3.6/site-packages/django/views/decorators/csrf.py", line 54, in wrapped_view
    return view_func(*args, **kwargs)
  File "/usr/local/lib/python3.6/site-packages/django/views/generic/base.py", line 68, in view
    return self.dispatch(request, *args, **kwargs)
  File "/usr/local/lib/python3.6/site-packages/rest_framework/views.py", line 495, in dispatch
    response = self.handle_exception(exc)
  File "/usr/local/lib/python3.6/site-packages/rest_framework/views.py", line 455, in handle_exception
    self.raise_uncaught_exception(exc)
  File "/usr/local/lib/python3.6/site-packages/rest_framework/views.py", line 492, in dispatch
    response = handler(request, *args, **kwargs)
  File "/app/api/views/api_view.py", line 17, in get
    test_task.apply_async((7), countdown=3)
  File "/usr/local/lib/python3.6/site-packages/celery/app/task.py", line 513, in apply_async
    check_arguments(*(args or ()), **(kwargs or {}))
TypeError: test_task() argument after * must be an iterable, not int
"GET /api/v1/deploys/1/ HTTP/1.1" 500 89951
Internal Server Error: /api/v1/deploys/1/
Traceback (most recent call last):
  File "/usr/local/lib/python3.6/site-packages/django/core/handlers/exception.py", line 34, in inner
    response = get_response(request)
  File "/usr/local/lib/python3.6/site-packages/django/core/handlers/base.py", line 126, in _get_response
    response = self.process_exception_by_middleware(e, request)
  File "/usr/local/lib/python3.6/site-packages/django/core/handlers/base.py", line 124, in _get_response
    response = wrapped_callback(request, *callback_args, **callback_kwargs)
  File "/usr/local/lib/python3.6/site-packages/django/views/decorators/csrf.py", line 54, in wrapped_view
    return view_func(*args, **kwargs)
  File "/usr/local/lib/python3.6/site-packages/django/views/generic/base.py", line 68, in view
    return self.dispatch(request, *args, **kwargs)
  File "/usr/local/lib/python3.6/site-packages/rest_framework/views.py", line 495, in dispatch
    response = self.handle_exception(exc)
  File "/usr/local/lib/python3.6/site-packages/rest_framework/views.py", line 455, in handle_exception
    self.raise_uncaught_exception(exc)
  File "/usr/local/lib/python3.6/site-packages/rest_framework/views.py", line 492, in dispatch
    response = handler(request, *args, **kwargs)
  File "/app/api/views/api_view.py", line 17, in get
    test_task.apply_async((2, 2), countdown=3)
  File "/usr/local/lib/python3.6/site-packages/celery/app/task.py", line 513, in apply_async
    check_arguments(*(args or ()), **(kwargs or {}))
TypeError: test_task() takes 1 positional argument but 2 were given
"GET /api/v1/deploys/1/ HTTP/1.1" 500 89957
Internal Server Error: /api/v1/deploys/1/
Traceback (most recent call last):
  File "/usr/local/lib/python3.6/site-packages/django/core/handlers/exception.py", line 34, in inner
    response = get_response(request)
  File "/usr/local/lib/python3.6/site-packages/django/core/handlers/base.py", line 126, in _get_response
    response = self.process_exception_by_middleware(e, request)
  File "/usr/local/lib/python3.6/site-packages/django/core/handlers/base.py", line 124, in _get_response
    response = wrapped_callback(request, *callback_args, **callback_kwargs)
  File "/usr/local/lib/python3.6/site-packages/django/views/decorators/csrf.py", line 54, in wrapped_view
    return view_func(*args, **kwargs)
  File "/usr/local/lib/python3.6/site-packages/django/views/generic/base.py", line 68, in view
    return self.dispatch(request, *args, **kwargs)
  File "/usr/local/lib/python3.6/site-packages/rest_framework/views.py", line 495, in dispatch
    response = self.handle_exception(exc)
  File "/usr/local/lib/python3.6/site-packages/rest_framework/views.py", line 455, in handle_exception
    self.raise_uncaught_exception(exc)
  File "/usr/local/lib/python3.6/site-packages/rest_framework/views.py", line 492, in dispatch
    response = handler(request, *args, **kwargs)
  File "/app/api/views/api_view.py", line 17, in get
    test_task.apply_async(("as"), countdown=3)
  File "/usr/local/lib/python3.6/site-packages/celery/app/task.py", line 513, in apply_async
    check_arguments(*(args or ()), **(kwargs or {}))
TypeError: test_task() takes 1 positional argument but 2 were given
"GET /api/v1/deploys/1/ HTTP/1.1" 500 89983
Internal Server Error: /api/v1/deploys/1/
Traceback (most recent call last):
  File "/usr/local/lib/python3.6/site-packages/django/core/handlers/exception.py", line 34, in inner
    response = get_response(request)
  File "/usr/local/lib/python3.6/site-packages/django/core/handlers/base.py", line 126, in _get_response
    response = self.process_exception_by_middleware(e, request)
  File "/usr/local/lib/python3.6/site-packages/django/core/handlers/base.py", line 124, in _get_response
    response = wrapped_callback(request, *callback_args, **callback_kwargs)
  File "/usr/local/lib/python3.6/site-packages/django/views/decorators/csrf.py", line 54, in wrapped_view
    return view_func(*args, **kwargs)
  File "/usr/local/lib/python3.6/site-packages/django/views/generic/base.py", line 68, in view
    return self.dispatch(request, *args, **kwargs)
  File "/usr/local/lib/python3.6/site-packages/rest_framework/views.py", line 495, in dispatch
    response = self.handle_exception(exc)
  File "/usr/local/lib/python3.6/site-packages/rest_framework/views.py", line 455, in handle_exception
    self.raise_uncaught_exception(exc)
  File "/usr/local/lib/python3.6/site-packages/rest_framework/views.py", line 492, in dispatch
    response = handler(request, *args, **kwargs)
  File "/app/api/views/api_view.py", line 17, in get
    test_task.apply_async(("as"), countdown=3)
  File "/usr/local/lib/python3.6/site-packages/celery/app/task.py", line 513, in apply_async
    check_arguments(*(args or ()), **(kwargs or {}))
TypeError: test_task() takes 1 positional argument but 2 were given
"GET /api/v1/deploys/1/ HTTP/1.1" 500 89983
Internal Server Error: /api/v1/deploys/1/
Traceback (most recent call last):
  File "/usr/local/lib/python3.6/site-packages/django/core/handlers/exception.py", line 34, in inner
    response = get_response(request)
  File "/usr/local/lib/python3.6/site-packages/django/core/handlers/base.py", line 126, in _get_response
    response = self.process_exception_by_middleware(e, request)
  File "/usr/local/lib/python3.6/site-packages/django/core/handlers/base.py", line 124, in _get_response
    response = wrapped_callback(request, *callback_args, **callback_kwargs)
  File "/usr/local/lib/python3.6/site-packages/django/views/decorators/csrf.py", line 54, in wrapped_view
    return view_func(*args, **kwargs)
  File "/usr/local/lib/python3.6/site-packages/django/views/generic/base.py", line 68, in view
    return self.dispatch(request, *args, **kwargs)
  File "/usr/local/lib/python3.6/site-packages/rest_framework/views.py", line 495, in dispatch
    response = self.handle_exception(exc)
  File "/usr/local/lib/python3.6/site-packages/rest_framework/views.py", line 455, in handle_exception
    self.raise_uncaught_exception(exc)
  File "/usr/local/lib/python3.6/site-packages/rest_framework/views.py", line 492, in dispatch
    response = handler(request, *args, **kwargs)
  File "/app/api/views/api_view.py", line 17, in get
    test_task.apply_async(("as"), countdown=3)
  File "/usr/local/lib/python3.6/site-packages/celery/app/task.py", line 513, in apply_async
    check_arguments(*(args or ()), **(kwargs or {}))
TypeError: test_task() takes 1 positional argument but 2 were given
"GET /api/v1/deploys/1/ HTTP/1.1" 500 89983
Internal Server Error: /api/v1/deploys/1/
Traceback (most recent call last):
  File "/usr/local/lib/python3.6/site-packages/django/core/handlers/exception.py", line 34, in inner
    response = get_response(request)
  File "/usr/local/lib/python3.6/site-packages/django/core/handlers/base.py", line 126, in _get_response
    response = self.process_exception_by_middleware(e, request)
  File "/usr/local/lib/python3.6/site-packages/django/core/handlers/base.py", line 124, in _get_response
    response = wrapped_callback(request, *callback_args, **callback_kwargs)
  File "/usr/local/lib/python3.6/site-packages/django/views/decorators/csrf.py", line 54, in wrapped_view
    return view_func(*args, **kwargs)
  File "/usr/local/lib/python3.6/site-packages/django/views/generic/base.py", line 68, in view
    return self.dispatch(request, *args, **kwargs)
  File "/usr/local/lib/python3.6/site-packages/rest_framework/views.py", line 495, in dispatch
    response = self.handle_exception(exc)
  File "/usr/local/lib/python3.6/site-packages/rest_framework/views.py", line 455, in handle_exception
    self.raise_uncaught_exception(exc)
  File "/usr/local/lib/python3.6/site-packages/rest_framework/views.py", line 492, in dispatch
    response = handler(request, *args, **kwargs)
  File "/app/api/views/api_view.py", line 17, in get
    test_task.apply_async("asd", countdown=3)
  File "/usr/local/lib/python3.6/site-packages/celery/app/task.py", line 513, in apply_async
    check_arguments(*(args or ()), **(kwargs or {}))
TypeError: test_task() takes 1 positional argument but 3 were given
"GET /api/v1/deploys/1/ HTTP/1.1" 500 89982
Internal Server Error: /api/v1/deploys/1/
Traceback (most recent call last):
  File "/usr/local/lib/python3.6/site-packages/django/core/handlers/exception.py", line 34, in inner
    response = get_response(request)
  File "/usr/local/lib/python3.6/site-packages/django/core/handlers/base.py", line 126, in _get_response
    response = self.process_exception_by_middleware(e, request)
  File "/usr/local/lib/python3.6/site-packages/django/core/handlers/base.py", line 124, in _get_response
    response = wrapped_callback(request, *callback_args, **callback_kwargs)
  File "/usr/local/lib/python3.6/site-packages/django/views/decorators/csrf.py", line 54, in wrapped_view
    return view_func(*args, **kwargs)
  File "/usr/local/lib/python3.6/site-packages/django/views/generic/base.py", line 68, in view
    return self.dispatch(request, *args, **kwargs)
  File "/usr/local/lib/python3.6/site-packages/rest_framework/views.py", line 495, in dispatch
    response = self.handle_exception(exc)
  File "/usr/local/lib/python3.6/site-packages/rest_framework/views.py", line 455, in handle_exception
    self.raise_uncaught_exception(exc)
  File "/usr/local/lib/python3.6/site-packages/rest_framework/views.py", line 492, in dispatch
    response = handler(request, *args, **kwargs)
  File "/app/api/views/api_view.py", line 17, in get
    test_task.apply_async("asd", countdown=3)
  File "/usr/local/lib/python3.6/site-packages/celery/app/task.py", line 513, in apply_async
    check_arguments(*(args or ()), **(kwargs or {}))
TypeError: test_task() takes 1 positional argument but 3 were given
"GET /api/v1/deploys/1/ HTTP/1.1" 500 90231
"GET /api/v1/deploys/1/ HTTP/1.1" 200 10188
"GET /static/rest_framework/css/prettify.css HTTP/1.1" 304 0
"GET /static/rest_framework/css/bootstrap-tweaks.css HTTP/1.1" 304 0
"GET /static/rest_framework/css/bootstrap.min.css HTTP/1.1" 304 0
"GET /static/rest_framework/js/ajax-form.js HTTP/1.1" 304 0
"GET /static/rest_framework/js/jquery-3.3.1.min.js HTTP/1.1" 304 0
"GET /static/rest_framework/css/default.css HTTP/1.1" 304 0
"GET /static/rest_framework/js/csrf.js HTTP/1.1" 304 0
"GET /static/rest_framework/js/bootstrap.min.js HTTP/1.1" 304 0
"GET /static/rest_framework/js/prettify-min.js HTTP/1.1" 304 0
"GET /static/rest_framework/js/default.js HTTP/1.1" 304 0
"GET /static/rest_framework/img/grid.png HTTP/1.1" 304 0
"GET /api/v1/deploys/1/ HTTP/1.1" 200 10188
"GET /api/v1/deploys/1/ HTTP/1.1" 200 10188
"GET /api/v1/deploys/1/ HTTP/1.1" 200 10188
"GET /static/rest_framework/css/bootstrap-tweaks.css HTTP/1.1" 304 0
"GET /static/rest_framework/css/bootstrap.min.css HTTP/1.1" 304 0
"GET /static/rest_framework/css/prettify.css HTTP/1.1" 304 0
"GET /static/rest_framework/js/jquery-3.3.1.min.js HTTP/1.1" 304 0
"GET /static/rest_framework/js/ajax-form.js HTTP/1.1" 304 0
"GET /static/rest_framework/css/default.css HTTP/1.1" 304 0
"GET /static/rest_framework/js/csrf.js HTTP/1.1" 304 0
"GET /static/rest_framework/js/bootstrap.min.js HTTP/1.1" 304 0
"GET /static/rest_framework/js/prettify-min.js HTTP/1.1" 304 0
"GET /static/rest_framework/js/default.js HTTP/1.1" 304 0
"GET /static/rest_framework/img/grid.png HTTP/1.1" 304 0
"GET /api/v1/deploys/1/ HTTP/1.1" 200 10188
"GET /api/v1/deploys/1/ HTTP/1.1" 200 10188
"GET /api/v1/deploys/1/ HTTP/1.1" 200 10188
"GET /api/v1/deploys/1/ HTTP/1.1" 200 10188
"GET /api/v1/deploys/1/ HTTP/1.1" 200 10188
"GET /api/v1/deploys/1/ HTTP/1.1" 200 10188
"GET /api/v1/deploys/1/ HTTP/1.1" 200 10188
"GET /api/v1/deploys/1/ HTTP/1.1" 200 10188
"GET /api/v1/deploys/1/ HTTP/1.1" 200 10188
"GET /api/v1/deploys/1/ HTTP/1.1" 200 10188
"GET /api/v1/deploys/1/ HTTP/1.1" 200 10188
"GET /api/v1/deploys/1/ HTTP/1.1" 200 10188
"GET /api/v1/deploys/1/ HTTP/1.1" 200 10188
"GET /static/rest_framework/css/bootstrap.min.css HTTP/1.1" 304 0
"GET /static/rest_framework/css/bootstrap-tweaks.css HTTP/1.1" 304 0
"GET /static/rest_framework/css/prettify.css HTTP/1.1" 304 0
"GET /static/rest_framework/css/default.css HTTP/1.1" 304 0
"GET /static/rest_framework/js/jquery-3.3.1.min.js HTTP/1.1" 304 0
"GET /static/rest_framework/js/ajax-form.js HTTP/1.1" 304 0
"GET /static/rest_framework/js/csrf.js HTTP/1.1" 304 0
"GET /static/rest_framework/js/bootstrap.min.js HTTP/1.1" 304 0
"GET /static/rest_framework/js/prettify-min.js HTTP/1.1" 304 0
"GET /static/rest_framework/js/default.js HTTP/1.1" 304 0
"GET /static/rest_framework/img/grid.png HTTP/1.1" 304 0
"GET /api/v1/deploys/1/ HTTP/1.1" 200 10188
Internal Server Error: /api/v1/deploys/1/
Traceback (most recent call last):
  File "/usr/local/lib/python3.6/site-packages/django/core/handlers/exception.py", line 34, in inner
    response = get_response(request)
  File "/usr/local/lib/python3.6/site-packages/django/core/handlers/base.py", line 126, in _get_response
    response = self.process_exception_by_middleware(e, request)
  File "/usr/local/lib/python3.6/site-packages/django/core/handlers/base.py", line 124, in _get_response
    response = wrapped_callback(request, *callback_args, **callback_kwargs)
  File "/usr/local/lib/python3.6/site-packages/django/views/decorators/csrf.py", line 54, in wrapped_view
    return view_func(*args, **kwargs)
  File "/usr/local/lib/python3.6/site-packages/django/views/generic/base.py", line 68, in view
    return self.dispatch(request, *args, **kwargs)
  File "/usr/local/lib/python3.6/site-packages/rest_framework/views.py", line 495, in dispatch
    response = self.handle_exception(exc)
  File "/usr/local/lib/python3.6/site-packages/rest_framework/views.py", line 455, in handle_exception
    self.raise_uncaught_exception(exc)
  File "/usr/local/lib/python3.6/site-packages/rest_framework/views.py", line 492, in dispatch
    response = handler(request, *args, **kwargs)
  File "/app/api/views/api_view.py", line 17, in get
    test_task.apply_async(countdown=60, expires=120)
  File "/usr/local/lib/python3.6/site-packages/celery/app/task.py", line 513, in apply_async
    check_arguments(*(args or ()), **(kwargs or {}))
TypeError: test_task() missing 1 required positional argument: 'num'
"GET /api/v1/deploys/1/ HTTP/1.1" 500 90219
"GET /api/v1/deploys/1/ HTTP/1.1" 200 10188
"GET /static/rest_framework/css/bootstrap-tweaks.css HTTP/1.1" 304 0
"GET /static/rest_framework/css/bootstrap.min.css HTTP/1.1" 304 0
"GET /static/rest_framework/css/prettify.css HTTP/1.1" 304 0
"GET /static/rest_framework/css/default.css HTTP/1.1" 304 0
"GET /static/rest_framework/js/ajax-form.js HTTP/1.1" 304 0
"GET /static/rest_framework/js/jquery-3.3.1.min.js HTTP/1.1" 304 0
"GET /static/rest_framework/js/csrf.js HTTP/1.1" 304 0
"GET /static/rest_framework/js/bootstrap.min.js HTTP/1.1" 304 0
"GET /static/rest_framework/js/prettify-min.js HTTP/1.1" 304 0
"GET /static/rest_framework/js/default.js HTTP/1.1" 304 0
"GET /static/rest_framework/img/grid.png HTTP/1.1" 304 0
"GET /api/v1/deploys/1/ HTTP/1.1" 200 10188
"GET /api/v1/deploys/1/ HTTP/1.1" 200 10188
"GET /api/v1/deploys/1/ HTTP/1.1" 200 10188
"GET /api/v1/deploys/1/ HTTP/1.1" 200 10188
"GET /api/v1/deploys/1/ HTTP/1.1" 200 10188
"GET /static/rest_framework/css/bootstrap.min.css HTTP/1.1" 304 0
"GET /static/rest_framework/css/prettify.css HTTP/1.1" 304 0
"GET /static/rest_framework/css/bootstrap-tweaks.css HTTP/1.1" 304 0
"GET /static/rest_framework/css/default.css HTTP/1.1" 304 0
"GET /static/rest_framework/js/jquery-3.3.1.min.js HTTP/1.1" 304 0
"GET /static/rest_framework/js/ajax-form.js HTTP/1.1" 304 0
"GET /static/rest_framework/js/csrf.js HTTP/1.1" 304 0
"GET /static/rest_framework/js/bootstrap.min.js HTTP/1.1" 304 0
"GET /static/rest_framework/js/prettify-min.js HTTP/1.1" 304 0
"GET /static/rest_framework/js/default.js HTTP/1.1" 304 0
"GET /static/rest_framework/img/grid.png HTTP/1.1" 304 0
"GET /api/v1/deploys/1/ HTTP/1.1" 200 10188
"GET /static/rest_framework/css/bootstrap-tweaks.css HTTP/1.1" 304 0
"GET /static/rest_framework/css/bootstrap.min.css HTTP/1.1" 304 0
"GET /static/rest_framework/css/prettify.css HTTP/1.1" 304 0
"GET /static/rest_framework/css/default.css HTTP/1.1" 304 0
"GET /static/rest_framework/js/ajax-form.js HTTP/1.1" 304 0
"GET /static/rest_framework/js/jquery-3.3.1.min.js HTTP/1.1" 304 0
"GET /static/rest_framework/js/csrf.js HTTP/1.1" 304 0
"GET /static/rest_framework/js/bootstrap.min.js HTTP/1.1" 304 0
"GET /static/rest_framework/js/prettify-min.js HTTP/1.1" 304 0
"GET /static/rest_framework/js/default.js HTTP/1.1" 304 0
"GET /static/rest_framework/img/grid.png HTTP/1.1" 304 0
Not Found: /static/rest_framework/css/bootstrap-tweaks.css
Not Found: /static/rest_framework/js/jquery-3.3.1.min.js
Not Found: /static/rest_framework/js/ajax-form.js
Not Found: /static/rest_framework/js/csrf.js
Not Found: /static/rest_framework/js/bootstrap.min.js
Not Found: /static/rest_framework/js/prettify-min.js
Not Found: /static/rest_framework/js/default.js
Not Found: /static/rest_framework/css/bootstrap.min.css
Not Found: /static/rest_framework/css/default.css
Not Found: /static/rest_framework/css/prettify.css
Not Found: /static/rest_framework/css/bootstrap-tweaks.css
Not Found: /static/rest_framework/css/default.css
Not Found: /static/rest_framework/js/jquery-3.3.1.min.js
Not Found: /static/rest_framework/js/ajax-form.js
Not Found: /static/rest_framework/js/csrf.js
Not Found: /static/rest_framework/js/bootstrap.min.js
Not Found: /static/rest_framework/js/prettify-min.js
Not Found: /static/rest_framework/js/default.js
